// 
// Decompiled by Procyon v0.5.36
// 

package net.minecraft.world.gen.structure;

import java.util.Iterator;
import java.util.Collections;
import com.google.common.collect.Lists;
import java.util.List;
import net.minecraft.block.BlockPrismarine;
import net.minecraft.init.Blocks;
import net.minecraft.block.material.Material;
import net.minecraft.entity.IEntityLivingData;
import net.minecraft.entity.Entity;
import net.minecraft.entity.monster.EntityElderGuardian;
import net.minecraft.util.math.Vec3i;
import net.minecraft.util.math.BlockPos;
import net.minecraft.world.gen.structure.template.TemplateManager;
import net.minecraft.nbt.NBTTagCompound;
import net.minecraft.block.state.IBlockState;
import net.minecraft.world.World;
import java.util.Random;
import net.minecraft.util.EnumFacing;

public class StructureOceanMonumentPieces
{
    public static void registerOceanMonumentPieces() {
        MapGenStructureIO.registerStructureComponent(MonumentBuilding.class, "OMB");
        MapGenStructureIO.registerStructureComponent(MonumentCoreRoom.class, "OMCR");
        MapGenStructureIO.registerStructureComponent(DoubleXRoom.class, "OMDXR");
        MapGenStructureIO.registerStructureComponent(DoubleXYRoom.class, "OMDXYR");
        MapGenStructureIO.registerStructureComponent(DoubleYRoom.class, "OMDYR");
        MapGenStructureIO.registerStructureComponent(DoubleYZRoom.class, "OMDYZR");
        MapGenStructureIO.registerStructureComponent(DoubleZRoom.class, "OMDZR");
        MapGenStructureIO.registerStructureComponent(EntryRoom.class, "OMEntry");
        MapGenStructureIO.registerStructureComponent(Penthouse.class, "OMPenthouse");
        MapGenStructureIO.registerStructureComponent(SimpleRoom.class, "OMSimple");
        MapGenStructureIO.registerStructureComponent(SimpleTopRoom.class, "OMSimpleT");
    }
    
    static class FitSimpleRoomHelper implements MonumentRoomFitHelper
    {
        @Override
        public Piece create(final EnumFacing lllllllllllllIllllIIIllIlIllIllI, final RoomDefinition lllllllllllllIllllIIIllIlIllIlIl, final Random lllllllllllllIllllIIIllIlIllIlll) {
            lllllllllllllIllllIIIllIlIllIlIl.claimed = true;
            return new SimpleRoom(lllllllllllllIllllIIIllIlIllIllI, lllllllllllllIllllIIIllIlIllIlIl, lllllllllllllIllllIIIllIlIllIlll);
        }
        
        private FitSimpleRoomHelper() {
        }
        
        @Override
        public boolean fits(final RoomDefinition lllllllllllllIllllIIIllIlIlllllI) {
            return true;
        }
    }
    
    public static class SimpleRoom extends Piece
    {
        private /* synthetic */ int mainDesign;
        
        @Override
        public boolean addComponentParts(final World lllllllllllIIlIIIIIIlIIIlIIIllll, final Random lllllllllllIIlIIIIIIlIIIlIIIlIIl, final StructureBoundingBox lllllllllllIIlIIIIIIlIIIlIIIlIII) {
            if (this.roomDefinition.index / 25 > 0) {
                this.generateDefaultFloor(lllllllllllIIlIIIIIIlIIIlIIIllll, lllllllllllIIlIIIIIIlIIIlIIIlIII, 0, 0, this.roomDefinition.hasOpening[EnumFacing.DOWN.getIndex()]);
            }
            if (this.roomDefinition.connections[EnumFacing.UP.getIndex()] == null) {
                this.generateBoxOnFillOnly(lllllllllllIIlIIIIIIlIIIlIIIllll, lllllllllllIIlIIIIIIlIIIlIIIlIII, 1, 4, 1, 6, 4, 6, SimpleRoom.ROUGH_PRISMARINE);
            }
            final boolean lllllllllllIIlIIIIIIlIIIlIIIllII = this.mainDesign != 0 && lllllllllllIIlIIIIIIlIIIlIIIlIIl.nextBoolean() && !this.roomDefinition.hasOpening[EnumFacing.DOWN.getIndex()] && !this.roomDefinition.hasOpening[EnumFacing.UP.getIndex()] && this.roomDefinition.countOpenings() > 1;
            if (this.mainDesign == 0) {
                this.fillWithBlocks(lllllllllllIIlIIIIIIlIIIlIIIllll, lllllllllllIIlIIIIIIlIIIlIIIlIII, 0, 1, 0, 2, 1, 2, SimpleRoom.BRICKS_PRISMARINE, SimpleRoom.BRICKS_PRISMARINE, false);
                this.fillWithBlocks(lllllllllllIIlIIIIIIlIIIlIIIllll, lllllllllllIIlIIIIIIlIIIlIIIlIII, 0, 3, 0, 2, 3, 2, SimpleRoom.BRICKS_PRISMARINE, SimpleRoom.BRICKS_PRISMARINE, false);
                this.fillWithBlocks(lllllllllllIIlIIIIIIlIIIlIIIllll, lllllllllllIIlIIIIIIlIIIlIIIlIII, 0, 2, 0, 0, 2, 2, SimpleRoom.ROUGH_PRISMARINE, SimpleRoom.ROUGH_PRISMARINE, false);
                this.fillWithBlocks(lllllllllllIIlIIIIIIlIIIlIIIllll, lllllllllllIIlIIIIIIlIIIlIIIlIII, 1, 2, 0, 2, 2, 0, SimpleRoom.ROUGH_PRISMARINE, SimpleRoom.ROUGH_PRISMARINE, false);
                this.setBlockState(lllllllllllIIlIIIIIIlIIIlIIIllll, SimpleRoom.SEA_LANTERN, 1, 2, 1, lllllllllllIIlIIIIIIlIIIlIIIlIII);
                this.fillWithBlocks(lllllllllllIIlIIIIIIlIIIlIIIllll, lllllllllllIIlIIIIIIlIIIlIIIlIII, 5, 1, 0, 7, 1, 2, SimpleRoom.BRICKS_PRISMARINE, SimpleRoom.BRICKS_PRISMARINE, false);
                this.fillWithBlocks(lllllllllllIIlIIIIIIlIIIlIIIllll, lllllllllllIIlIIIIIIlIIIlIIIlIII, 5, 3, 0, 7, 3, 2, SimpleRoom.BRICKS_PRISMARINE, SimpleRoom.BRICKS_PRISMARINE, false);
                this.fillWithBlocks(lllllllllllIIlIIIIIIlIIIlIIIllll, lllllllllllIIlIIIIIIlIIIlIIIlIII, 7, 2, 0, 7, 2, 2, SimpleRoom.ROUGH_PRISMARINE, SimpleRoom.ROUGH_PRISMARINE, false);
                this.fillWithBlocks(lllllllllllIIlIIIIIIlIIIlIIIllll, lllllllllllIIlIIIIIIlIIIlIIIlIII, 5, 2, 0, 6, 2, 0, SimpleRoom.ROUGH_PRISMARINE, SimpleRoom.ROUGH_PRISMARINE, false);
                this.setBlockState(lllllllllllIIlIIIIIIlIIIlIIIllll, SimpleRoom.SEA_LANTERN, 6, 2, 1, lllllllllllIIlIIIIIIlIIIlIIIlIII);
                this.fillWithBlocks(lllllllllllIIlIIIIIIlIIIlIIIllll, lllllllllllIIlIIIIIIlIIIlIIIlIII, 0, 1, 5, 2, 1, 7, SimpleRoom.BRICKS_PRISMARINE, SimpleRoom.BRICKS_PRISMARINE, false);
                this.fillWithBlocks(lllllllllllIIlIIIIIIlIIIlIIIllll, lllllllllllIIlIIIIIIlIIIlIIIlIII, 0, 3, 5, 2, 3, 7, SimpleRoom.BRICKS_PRISMARINE, SimpleRoom.BRICKS_PRISMARINE, false);
                this.fillWithBlocks(lllllllllllIIlIIIIIIlIIIlIIIllll, lllllllllllIIlIIIIIIlIIIlIIIlIII, 0, 2, 5, 0, 2, 7, SimpleRoom.ROUGH_PRISMARINE, SimpleRoom.ROUGH_PRISMARINE, false);
                this.fillWithBlocks(lllllllllllIIlIIIIIIlIIIlIIIllll, lllllllllllIIlIIIIIIlIIIlIIIlIII, 1, 2, 7, 2, 2, 7, SimpleRoom.ROUGH_PRISMARINE, SimpleRoom.ROUGH_PRISMARINE, false);
                this.setBlockState(lllllllllllIIlIIIIIIlIIIlIIIllll, SimpleRoom.SEA_LANTERN, 1, 2, 6, lllllllllllIIlIIIIIIlIIIlIIIlIII);
                this.fillWithBlocks(lllllllllllIIlIIIIIIlIIIlIIIllll, lllllllllllIIlIIIIIIlIIIlIIIlIII, 5, 1, 5, 7, 1, 7, SimpleRoom.BRICKS_PRISMARINE, SimpleRoom.BRICKS_PRISMARINE, false);
                this.fillWithBlocks(lllllllllllIIlIIIIIIlIIIlIIIllll, lllllllllllIIlIIIIIIlIIIlIIIlIII, 5, 3, 5, 7, 3, 7, SimpleRoom.BRICKS_PRISMARINE, SimpleRoom.BRICKS_PRISMARINE, false);
                this.fillWithBlocks(lllllllllllIIlIIIIIIlIIIlIIIllll, lllllllllllIIlIIIIIIlIIIlIIIlIII, 7, 2, 5, 7, 2, 7, SimpleRoom.ROUGH_PRISMARINE, SimpleRoom.ROUGH_PRISMARINE, false);
                this.fillWithBlocks(lllllllllllIIlIIIIIIlIIIlIIIllll, lllllllllllIIlIIIIIIlIIIlIIIlIII, 5, 2, 7, 6, 2, 7, SimpleRoom.ROUGH_PRISMARINE, SimpleRoom.ROUGH_PRISMARINE, false);
                this.setBlockState(lllllllllllIIlIIIIIIlIIIlIIIllll, SimpleRoom.SEA_LANTERN, 6, 2, 6, lllllllllllIIlIIIIIIlIIIlIIIlIII);
                if (this.roomDefinition.hasOpening[EnumFacing.SOUTH.getIndex()]) {
                    this.fillWithBlocks(lllllllllllIIlIIIIIIlIIIlIIIllll, lllllllllllIIlIIIIIIlIIIlIIIlIII, 3, 3, 0, 4, 3, 0, SimpleRoom.BRICKS_PRISMARINE, SimpleRoom.BRICKS_PRISMARINE, false);
                }
                else {
                    this.fillWithBlocks(lllllllllllIIlIIIIIIlIIIlIIIllll, lllllllllllIIlIIIIIIlIIIlIIIlIII, 3, 3, 0, 4, 3, 1, SimpleRoom.BRICKS_PRISMARINE, SimpleRoom.BRICKS_PRISMARINE, false);
                    this.fillWithBlocks(lllllllllllIIlIIIIIIlIIIlIIIllll, lllllllllllIIlIIIIIIlIIIlIIIlIII, 3, 2, 0, 4, 2, 0, SimpleRoom.ROUGH_PRISMARINE, SimpleRoom.ROUGH_PRISMARINE, false);
                    this.fillWithBlocks(lllllllllllIIlIIIIIIlIIIlIIIllll, lllllllllllIIlIIIIIIlIIIlIIIlIII, 3, 1, 0, 4, 1, 1, SimpleRoom.BRICKS_PRISMARINE, SimpleRoom.BRICKS_PRISMARINE, false);
                }
                if (this.roomDefinition.hasOpening[EnumFacing.NORTH.getIndex()]) {
                    this.fillWithBlocks(lllllllllllIIlIIIIIIlIIIlIIIllll, lllllllllllIIlIIIIIIlIIIlIIIlIII, 3, 3, 7, 4, 3, 7, SimpleRoom.BRICKS_PRISMARINE, SimpleRoom.BRICKS_PRISMARINE, false);
                }
                else {
                    this.fillWithBlocks(lllllllllllIIlIIIIIIlIIIlIIIllll, lllllllllllIIlIIIIIIlIIIlIIIlIII, 3, 3, 6, 4, 3, 7, SimpleRoom.BRICKS_PRISMARINE, SimpleRoom.BRICKS_PRISMARINE, false);
                    this.fillWithBlocks(lllllllllllIIlIIIIIIlIIIlIIIllll, lllllllllllIIlIIIIIIlIIIlIIIlIII, 3, 2, 7, 4, 2, 7, SimpleRoom.ROUGH_PRISMARINE, SimpleRoom.ROUGH_PRISMARINE, false);
                    this.fillWithBlocks(lllllllllllIIlIIIIIIlIIIlIIIllll, lllllllllllIIlIIIIIIlIIIlIIIlIII, 3, 1, 6, 4, 1, 7, SimpleRoom.BRICKS_PRISMARINE, SimpleRoom.BRICKS_PRISMARINE, false);
                }
                if (this.roomDefinition.hasOpening[EnumFacing.WEST.getIndex()]) {
                    this.fillWithBlocks(lllllllllllIIlIIIIIIlIIIlIIIllll, lllllllllllIIlIIIIIIlIIIlIIIlIII, 0, 3, 3, 0, 3, 4, SimpleRoom.BRICKS_PRISMARINE, SimpleRoom.BRICKS_PRISMARINE, false);
                }
                else {
                    this.fillWithBlocks(lllllllllllIIlIIIIIIlIIIlIIIllll, lllllllllllIIlIIIIIIlIIIlIIIlIII, 0, 3, 3, 1, 3, 4, SimpleRoom.BRICKS_PRISMARINE, SimpleRoom.BRICKS_PRISMARINE, false);
                    this.fillWithBlocks(lllllllllllIIlIIIIIIlIIIlIIIllll, lllllllllllIIlIIIIIIlIIIlIIIlIII, 0, 2, 3, 0, 2, 4, SimpleRoom.ROUGH_PRISMARINE, SimpleRoom.ROUGH_PRISMARINE, false);
                    this.fillWithBlocks(lllllllllllIIlIIIIIIlIIIlIIIllll, lllllllllllIIlIIIIIIlIIIlIIIlIII, 0, 1, 3, 1, 1, 4, SimpleRoom.BRICKS_PRISMARINE, SimpleRoom.BRICKS_PRISMARINE, false);
                }
                if (this.roomDefinition.hasOpening[EnumFacing.EAST.getIndex()]) {
                    this.fillWithBlocks(lllllllllllIIlIIIIIIlIIIlIIIllll, lllllllllllIIlIIIIIIlIIIlIIIlIII, 7, 3, 3, 7, 3, 4, SimpleRoom.BRICKS_PRISMARINE, SimpleRoom.BRICKS_PRISMARINE, false);
                }
                else {
                    this.fillWithBlocks(lllllllllllIIlIIIIIIlIIIlIIIllll, lllllllllllIIlIIIIIIlIIIlIIIlIII, 6, 3, 3, 7, 3, 4, SimpleRoom.BRICKS_PRISMARINE, SimpleRoom.BRICKS_PRISMARINE, false);
                    this.fillWithBlocks(lllllllllllIIlIIIIIIlIIIlIIIllll, lllllllllllIIlIIIIIIlIIIlIIIlIII, 7, 2, 3, 7, 2, 4, SimpleRoom.ROUGH_PRISMARINE, SimpleRoom.ROUGH_PRISMARINE, false);
                    this.fillWithBlocks(lllllllllllIIlIIIIIIlIIIlIIIllll, lllllllllllIIlIIIIIIlIIIlIIIlIII, 6, 1, 3, 7, 1, 4, SimpleRoom.BRICKS_PRISMARINE, SimpleRoom.BRICKS_PRISMARINE, false);
                }
            }
            else if (this.mainDesign == 1) {
                this.fillWithBlocks(lllllllllllIIlIIIIIIlIIIlIIIllll, lllllllllllIIlIIIIIIlIIIlIIIlIII, 2, 1, 2, 2, 3, 2, SimpleRoom.BRICKS_PRISMARINE, SimpleRoom.BRICKS_PRISMARINE, false);
                this.fillWithBlocks(lllllllllllIIlIIIIIIlIIIlIIIllll, lllllllllllIIlIIIIIIlIIIlIIIlIII, 2, 1, 5, 2, 3, 5, SimpleRoom.BRICKS_PRISMARINE, SimpleRoom.BRICKS_PRISMARINE, false);
                this.fillWithBlocks(lllllllllllIIlIIIIIIlIIIlIIIllll, lllllllllllIIlIIIIIIlIIIlIIIlIII, 5, 1, 5, 5, 3, 5, SimpleRoom.BRICKS_PRISMARINE, SimpleRoom.BRICKS_PRISMARINE, false);
                this.fillWithBlocks(lllllllllllIIlIIIIIIlIIIlIIIllll, lllllllllllIIlIIIIIIlIIIlIIIlIII, 5, 1, 2, 5, 3, 2, SimpleRoom.BRICKS_PRISMARINE, SimpleRoom.BRICKS_PRISMARINE, false);
                this.setBlockState(lllllllllllIIlIIIIIIlIIIlIIIllll, SimpleRoom.SEA_LANTERN, 2, 2, 2, lllllllllllIIlIIIIIIlIIIlIIIlIII);
                this.setBlockState(lllllllllllIIlIIIIIIlIIIlIIIllll, SimpleRoom.SEA_LANTERN, 2, 2, 5, lllllllllllIIlIIIIIIlIIIlIIIlIII);
                this.setBlockState(lllllllllllIIlIIIIIIlIIIlIIIllll, SimpleRoom.SEA_LANTERN, 5, 2, 5, lllllllllllIIlIIIIIIlIIIlIIIlIII);
                this.setBlockState(lllllllllllIIlIIIIIIlIIIlIIIllll, SimpleRoom.SEA_LANTERN, 5, 2, 2, lllllllllllIIlIIIIIIlIIIlIIIlIII);
                this.fillWithBlocks(lllllllllllIIlIIIIIIlIIIlIIIllll, lllllllllllIIlIIIIIIlIIIlIIIlIII, 0, 1, 0, 1, 3, 0, SimpleRoom.BRICKS_PRISMARINE, SimpleRoom.BRICKS_PRISMARINE, false);
                this.fillWithBlocks(lllllllllllIIlIIIIIIlIIIlIIIllll, lllllllllllIIlIIIIIIlIIIlIIIlIII, 0, 1, 1, 0, 3, 1, SimpleRoom.BRICKS_PRISMARINE, SimpleRoom.BRICKS_PRISMARINE, false);
                this.fillWithBlocks(lllllllllllIIlIIIIIIlIIIlIIIllll, lllllllllllIIlIIIIIIlIIIlIIIlIII, 0, 1, 7, 1, 3, 7, SimpleRoom.BRICKS_PRISMARINE, SimpleRoom.BRICKS_PRISMARINE, false);
                this.fillWithBlocks(lllllllllllIIlIIIIIIlIIIlIIIllll, lllllllllllIIlIIIIIIlIIIlIIIlIII, 0, 1, 6, 0, 3, 6, SimpleRoom.BRICKS_PRISMARINE, SimpleRoom.BRICKS_PRISMARINE, false);
                this.fillWithBlocks(lllllllllllIIlIIIIIIlIIIlIIIllll, lllllllllllIIlIIIIIIlIIIlIIIlIII, 6, 1, 7, 7, 3, 7, SimpleRoom.BRICKS_PRISMARINE, SimpleRoom.BRICKS_PRISMARINE, false);
                this.fillWithBlocks(lllllllllllIIlIIIIIIlIIIlIIIllll, lllllllllllIIlIIIIIIlIIIlIIIlIII, 7, 1, 6, 7, 3, 6, SimpleRoom.BRICKS_PRISMARINE, SimpleRoom.BRICKS_PRISMARINE, false);
                this.fillWithBlocks(lllllllllllIIlIIIIIIlIIIlIIIllll, lllllllllllIIlIIIIIIlIIIlIIIlIII, 6, 1, 0, 7, 3, 0, SimpleRoom.BRICKS_PRISMARINE, SimpleRoom.BRICKS_PRISMARINE, false);
                this.fillWithBlocks(lllllllllllIIlIIIIIIlIIIlIIIllll, lllllllllllIIlIIIIIIlIIIlIIIlIII, 7, 1, 1, 7, 3, 1, SimpleRoom.BRICKS_PRISMARINE, SimpleRoom.BRICKS_PRISMARINE, false);
                this.setBlockState(lllllllllllIIlIIIIIIlIIIlIIIllll, SimpleRoom.ROUGH_PRISMARINE, 1, 2, 0, lllllllllllIIlIIIIIIlIIIlIIIlIII);
                this.setBlockState(lllllllllllIIlIIIIIIlIIIlIIIllll, SimpleRoom.ROUGH_PRISMARINE, 0, 2, 1, lllllllllllIIlIIIIIIlIIIlIIIlIII);
                this.setBlockState(lllllllllllIIlIIIIIIlIIIlIIIllll, SimpleRoom.ROUGH_PRISMARINE, 1, 2, 7, lllllllllllIIlIIIIIIlIIIlIIIlIII);
                this.setBlockState(lllllllllllIIlIIIIIIlIIIlIIIllll, SimpleRoom.ROUGH_PRISMARINE, 0, 2, 6, lllllllllllIIlIIIIIIlIIIlIIIlIII);
                this.setBlockState(lllllllllllIIlIIIIIIlIIIlIIIllll, SimpleRoom.ROUGH_PRISMARINE, 6, 2, 7, lllllllllllIIlIIIIIIlIIIlIIIlIII);
                this.setBlockState(lllllllllllIIlIIIIIIlIIIlIIIllll, SimpleRoom.ROUGH_PRISMARINE, 7, 2, 6, lllllllllllIIlIIIIIIlIIIlIIIlIII);
                this.setBlockState(lllllllllllIIlIIIIIIlIIIlIIIllll, SimpleRoom.ROUGH_PRISMARINE, 6, 2, 0, lllllllllllIIlIIIIIIlIIIlIIIlIII);
                this.setBlockState(lllllllllllIIlIIIIIIlIIIlIIIllll, SimpleRoom.ROUGH_PRISMARINE, 7, 2, 1, lllllllllllIIlIIIIIIlIIIlIIIlIII);
                if (!this.roomDefinition.hasOpening[EnumFacing.SOUTH.getIndex()]) {
                    this.fillWithBlocks(lllllllllllIIlIIIIIIlIIIlIIIllll, lllllllllllIIlIIIIIIlIIIlIIIlIII, 1, 3, 0, 6, 3, 0, SimpleRoom.BRICKS_PRISMARINE, SimpleRoom.BRICKS_PRISMARINE, false);
                    this.fillWithBlocks(lllllllllllIIlIIIIIIlIIIlIIIllll, lllllllllllIIlIIIIIIlIIIlIIIlIII, 1, 2, 0, 6, 2, 0, SimpleRoom.ROUGH_PRISMARINE, SimpleRoom.ROUGH_PRISMARINE, false);
                    this.fillWithBlocks(lllllllllllIIlIIIIIIlIIIlIIIllll, lllllllllllIIlIIIIIIlIIIlIIIlIII, 1, 1, 0, 6, 1, 0, SimpleRoom.BRICKS_PRISMARINE, SimpleRoom.BRICKS_PRISMARINE, false);
                }
                if (!this.roomDefinition.hasOpening[EnumFacing.NORTH.getIndex()]) {
                    this.fillWithBlocks(lllllllllllIIlIIIIIIlIIIlIIIllll, lllllllllllIIlIIIIIIlIIIlIIIlIII, 1, 3, 7, 6, 3, 7, SimpleRoom.BRICKS_PRISMARINE, SimpleRoom.BRICKS_PRISMARINE, false);
                    this.fillWithBlocks(lllllllllllIIlIIIIIIlIIIlIIIllll, lllllllllllIIlIIIIIIlIIIlIIIlIII, 1, 2, 7, 6, 2, 7, SimpleRoom.ROUGH_PRISMARINE, SimpleRoom.ROUGH_PRISMARINE, false);
                    this.fillWithBlocks(lllllllllllIIlIIIIIIlIIIlIIIllll, lllllllllllIIlIIIIIIlIIIlIIIlIII, 1, 1, 7, 6, 1, 7, SimpleRoom.BRICKS_PRISMARINE, SimpleRoom.BRICKS_PRISMARINE, false);
                }
                if (!this.roomDefinition.hasOpening[EnumFacing.WEST.getIndex()]) {
                    this.fillWithBlocks(lllllllllllIIlIIIIIIlIIIlIIIllll, lllllllllllIIlIIIIIIlIIIlIIIlIII, 0, 3, 1, 0, 3, 6, SimpleRoom.BRICKS_PRISMARINE, SimpleRoom.BRICKS_PRISMARINE, false);
                    this.fillWithBlocks(lllllllllllIIlIIIIIIlIIIlIIIllll, lllllllllllIIlIIIIIIlIIIlIIIlIII, 0, 2, 1, 0, 2, 6, SimpleRoom.ROUGH_PRISMARINE, SimpleRoom.ROUGH_PRISMARINE, false);
                    this.fillWithBlocks(lllllllllllIIlIIIIIIlIIIlIIIllll, lllllllllllIIlIIIIIIlIIIlIIIlIII, 0, 1, 1, 0, 1, 6, SimpleRoom.BRICKS_PRISMARINE, SimpleRoom.BRICKS_PRISMARINE, false);
                }
                if (!this.roomDefinition.hasOpening[EnumFacing.EAST.getIndex()]) {
                    this.fillWithBlocks(lllllllllllIIlIIIIIIlIIIlIIIllll, lllllllllllIIlIIIIIIlIIIlIIIlIII, 7, 3, 1, 7, 3, 6, SimpleRoom.BRICKS_PRISMARINE, SimpleRoom.BRICKS_PRISMARINE, false);
                    this.fillWithBlocks(lllllllllllIIlIIIIIIlIIIlIIIllll, lllllllllllIIlIIIIIIlIIIlIIIlIII, 7, 2, 1, 7, 2, 6, SimpleRoom.ROUGH_PRISMARINE, SimpleRoom.ROUGH_PRISMARINE, false);
                    this.fillWithBlocks(lllllllllllIIlIIIIIIlIIIlIIIllll, lllllllllllIIlIIIIIIlIIIlIIIlIII, 7, 1, 1, 7, 1, 6, SimpleRoom.BRICKS_PRISMARINE, SimpleRoom.BRICKS_PRISMARINE, false);
                }
            }
            else if (this.mainDesign == 2) {
                this.fillWithBlocks(lllllllllllIIlIIIIIIlIIIlIIIllll, lllllllllllIIlIIIIIIlIIIlIIIlIII, 0, 1, 0, 0, 1, 7, SimpleRoom.BRICKS_PRISMARINE, SimpleRoom.BRICKS_PRISMARINE, false);
                this.fillWithBlocks(lllllllllllIIlIIIIIIlIIIlIIIllll, lllllllllllIIlIIIIIIlIIIlIIIlIII, 7, 1, 0, 7, 1, 7, SimpleRoom.BRICKS_PRISMARINE, SimpleRoom.BRICKS_PRISMARINE, false);
                this.fillWithBlocks(lllllllllllIIlIIIIIIlIIIlIIIllll, lllllllllllIIlIIIIIIlIIIlIIIlIII, 1, 1, 0, 6, 1, 0, SimpleRoom.BRICKS_PRISMARINE, SimpleRoom.BRICKS_PRISMARINE, false);
                this.fillWithBlocks(lllllllllllIIlIIIIIIlIIIlIIIllll, lllllllllllIIlIIIIIIlIIIlIIIlIII, 1, 1, 7, 6, 1, 7, SimpleRoom.BRICKS_PRISMARINE, SimpleRoom.BRICKS_PRISMARINE, false);
                this.fillWithBlocks(lllllllllllIIlIIIIIIlIIIlIIIllll, lllllllllllIIlIIIIIIlIIIlIIIlIII, 0, 2, 0, 0, 2, 7, SimpleRoom.DARK_PRISMARINE, SimpleRoom.DARK_PRISMARINE, false);
                this.fillWithBlocks(lllllllllllIIlIIIIIIlIIIlIIIllll, lllllllllllIIlIIIIIIlIIIlIIIlIII, 7, 2, 0, 7, 2, 7, SimpleRoom.DARK_PRISMARINE, SimpleRoom.DARK_PRISMARINE, false);
                this.fillWithBlocks(lllllllllllIIlIIIIIIlIIIlIIIllll, lllllllllllIIlIIIIIIlIIIlIIIlIII, 1, 2, 0, 6, 2, 0, SimpleRoom.DARK_PRISMARINE, SimpleRoom.DARK_PRISMARINE, false);
                this.fillWithBlocks(lllllllllllIIlIIIIIIlIIIlIIIllll, lllllllllllIIlIIIIIIlIIIlIIIlIII, 1, 2, 7, 6, 2, 7, SimpleRoom.DARK_PRISMARINE, SimpleRoom.DARK_PRISMARINE, false);
                this.fillWithBlocks(lllllllllllIIlIIIIIIlIIIlIIIllll, lllllllllllIIlIIIIIIlIIIlIIIlIII, 0, 3, 0, 0, 3, 7, SimpleRoom.BRICKS_PRISMARINE, SimpleRoom.BRICKS_PRISMARINE, false);
                this.fillWithBlocks(lllllllllllIIlIIIIIIlIIIlIIIllll, lllllllllllIIlIIIIIIlIIIlIIIlIII, 7, 3, 0, 7, 3, 7, SimpleRoom.BRICKS_PRISMARINE, SimpleRoom.BRICKS_PRISMARINE, false);
                this.fillWithBlocks(lllllllllllIIlIIIIIIlIIIlIIIllll, lllllllllllIIlIIIIIIlIIIlIIIlIII, 1, 3, 0, 6, 3, 0, SimpleRoom.BRICKS_PRISMARINE, SimpleRoom.BRICKS_PRISMARINE, false);
                this.fillWithBlocks(lllllllllllIIlIIIIIIlIIIlIIIllll, lllllllllllIIlIIIIIIlIIIlIIIlIII, 1, 3, 7, 6, 3, 7, SimpleRoom.BRICKS_PRISMARINE, SimpleRoom.BRICKS_PRISMARINE, false);
                this.fillWithBlocks(lllllllllllIIlIIIIIIlIIIlIIIllll, lllllllllllIIlIIIIIIlIIIlIIIlIII, 0, 1, 3, 0, 2, 4, SimpleRoom.DARK_PRISMARINE, SimpleRoom.DARK_PRISMARINE, false);
                this.fillWithBlocks(lllllllllllIIlIIIIIIlIIIlIIIllll, lllllllllllIIlIIIIIIlIIIlIIIlIII, 7, 1, 3, 7, 2, 4, SimpleRoom.DARK_PRISMARINE, SimpleRoom.DARK_PRISMARINE, false);
                this.fillWithBlocks(lllllllllllIIlIIIIIIlIIIlIIIllll, lllllllllllIIlIIIIIIlIIIlIIIlIII, 3, 1, 0, 4, 2, 0, SimpleRoom.DARK_PRISMARINE, SimpleRoom.DARK_PRISMARINE, false);
                this.fillWithBlocks(lllllllllllIIlIIIIIIlIIIlIIIllll, lllllllllllIIlIIIIIIlIIIlIIIlIII, 3, 1, 7, 4, 2, 7, SimpleRoom.DARK_PRISMARINE, SimpleRoom.DARK_PRISMARINE, false);
                if (this.roomDefinition.hasOpening[EnumFacing.SOUTH.getIndex()]) {
                    this.generateWaterBox(lllllllllllIIlIIIIIIlIIIlIIIllll, lllllllllllIIlIIIIIIlIIIlIIIlIII, 3, 1, 0, 4, 2, 0, false);
                }
                if (this.roomDefinition.hasOpening[EnumFacing.NORTH.getIndex()]) {
                    this.generateWaterBox(lllllllllllIIlIIIIIIlIIIlIIIllll, lllllllllllIIlIIIIIIlIIIlIIIlIII, 3, 1, 7, 4, 2, 7, false);
                }
                if (this.roomDefinition.hasOpening[EnumFacing.WEST.getIndex()]) {
                    this.generateWaterBox(lllllllllllIIlIIIIIIlIIIlIIIllll, lllllllllllIIlIIIIIIlIIIlIIIlIII, 0, 1, 3, 0, 2, 4, false);
                }
                if (this.roomDefinition.hasOpening[EnumFacing.EAST.getIndex()]) {
                    this.generateWaterBox(lllllllllllIIlIIIIIIlIIIlIIIllll, lllllllllllIIlIIIIIIlIIIlIIIlIII, 7, 1, 3, 7, 2, 4, false);
                }
            }
            if (lllllllllllIIlIIIIIIlIIIlIIIllII) {
                this.fillWithBlocks(lllllllllllIIlIIIIIIlIIIlIIIllll, lllllllllllIIlIIIIIIlIIIlIIIlIII, 3, 1, 3, 4, 1, 4, SimpleRoom.BRICKS_PRISMARINE, SimpleRoom.BRICKS_PRISMARINE, false);
                this.fillWithBlocks(lllllllllllIIlIIIIIIlIIIlIIIllll, lllllllllllIIlIIIIIIlIIIlIIIlIII, 3, 2, 3, 4, 2, 4, SimpleRoom.ROUGH_PRISMARINE, SimpleRoom.ROUGH_PRISMARINE, false);
                this.fillWithBlocks(lllllllllllIIlIIIIIIlIIIlIIIllll, lllllllllllIIlIIIIIIlIIIlIIIlIII, 3, 3, 3, 4, 3, 4, SimpleRoom.BRICKS_PRISMARINE, SimpleRoom.BRICKS_PRISMARINE, false);
            }
            return true;
        }
        
        public SimpleRoom(final EnumFacing lllllllllllIIlIIIIIIlIIIlIIllIII, final RoomDefinition lllllllllllIIlIIIIIIlIIIlIIlIlll, final Random lllllllllllIIlIIIIIIlIIIlIIllIlI) {
            super(1, lllllllllllIIlIIIIIIlIIIlIIllIII, lllllllllllIIlIIIIIIlIIIlIIlIlll, 1, 1, 1);
            this.mainDesign = lllllllllllIIlIIIIIIlIIIlIIllIlI.nextInt(3);
        }
        
        public SimpleRoom() {
        }
    }
    
    public abstract static class Piece extends StructureComponent
    {
        protected static final /* synthetic */ int GRIDROOM_TOP_CONNECT_INDEX;
        protected static final /* synthetic */ int GRIDROOM_LEFTWING_CONNECT_INDEX;
        protected static final /* synthetic */ IBlockState ROUGH_PRISMARINE;
        protected static final /* synthetic */ IBlockState DOT_DECO_DATA;
        protected static final /* synthetic */ IBlockState SEA_LANTERN;
        protected /* synthetic */ RoomDefinition roomDefinition;
        protected static final /* synthetic */ int GRIDROOM_SOURCE_INDEX;
        protected static final /* synthetic */ IBlockState DARK_PRISMARINE;
        protected static final /* synthetic */ IBlockState WATER;
        protected static final /* synthetic */ int GRIDROOM_RIGHTWING_CONNECT_INDEX;
        protected static final /* synthetic */ IBlockState BRICKS_PRISMARINE;
        
        @Override
        protected void readStructureFromNBT(final NBTTagCompound llllllllllllIIlllIlIIlIlIIllIlll, final TemplateManager llllllllllllIIlllIlIIlIlIIllIllI) {
        }
        
        protected boolean spawnElder(final World llllllllllllIIlllIlIIlIIlIlIIIlI, final StructureBoundingBox llllllllllllIIlllIlIIlIIlIlIlIll, final int llllllllllllIIlllIlIIlIIlIlIlIlI, final int llllllllllllIIlllIlIIlIIlIIlllll, final int llllllllllllIIlllIlIIlIIlIIllllI) {
            final int llllllllllllIIlllIlIIlIIlIlIIlll = this.getXWithOffset(llllllllllllIIlllIlIIlIIlIlIlIlI, llllllllllllIIlllIlIIlIIlIIllllI);
            final int llllllllllllIIlllIlIIlIIlIlIIllI = this.getYWithOffset(llllllllllllIIlllIlIIlIIlIIlllll);
            final int llllllllllllIIlllIlIIlIIlIlIIlIl = this.getZWithOffset(llllllllllllIIlllIlIIlIIlIlIlIlI, llllllllllllIIlllIlIIlIIlIIllllI);
            if (llllllllllllIIlllIlIIlIIlIlIlIll.isVecInside(new BlockPos(llllllllllllIIlllIlIIlIIlIlIIlll, llllllllllllIIlllIlIIlIIlIlIIllI, llllllllllllIIlllIlIIlIIlIlIIlIl))) {
                final EntityElderGuardian llllllllllllIIlllIlIIlIIlIlIIlII = new EntityElderGuardian(llllllllllllIIlllIlIIlIIlIlIIIlI);
                llllllllllllIIlllIlIIlIIlIlIIlII.heal(llllllllllllIIlllIlIIlIIlIlIIlII.getMaxHealth());
                llllllllllllIIlllIlIIlIIlIlIIlII.setLocationAndAngles(llllllllllllIIlllIlIIlIIlIlIIlll + 0.5, llllllllllllIIlllIlIIlIIlIlIIllI, llllllllllllIIlllIlIIlIIlIlIIlIl + 0.5, 0.0f, 0.0f);
                llllllllllllIIlllIlIIlIIlIlIIlII.onInitialSpawn(llllllllllllIIlllIlIIlIIlIlIIIlI.getDifficultyForLocation(new BlockPos(llllllllllllIIlllIlIIlIIlIlIIlII)), null);
                llllllllllllIIlllIlIIlIIlIlIIIlI.spawnEntityInWorld(llllllllllllIIlllIlIIlIIlIlIIlII);
                return true;
            }
            return false;
        }
        
        protected void generateWaterBox(final World llllllllllllIIlllIlIIlIlIIlIIlll, final StructureBoundingBox llllllllllllIIlllIlIIlIlIIlIIllI, final int llllllllllllIIlllIlIIlIlIIIllIII, final int llllllllllllIIlllIlIIlIlIIlIIlII, final int llllllllllllIIlllIlIIlIlIIIlIllI, final int llllllllllllIIlllIlIIlIlIIIlIlIl, final int llllllllllllIIlllIlIIlIlIIlIIIIl, final int llllllllllllIIlllIlIIlIlIIlIIIII, final boolean llllllllllllIIlllIlIIlIlIIIlllll) {
            for (int llllllllllllIIlllIlIIlIlIIIllllI = llllllllllllIIlllIlIIlIlIIlIIlII; llllllllllllIIlllIlIIlIlIIIllllI <= llllllllllllIIlllIlIIlIlIIlIIIIl; ++llllllllllllIIlllIlIIlIlIIIllllI) {
                for (int llllllllllllIIlllIlIIlIlIIIlllIl = llllllllllllIIlllIlIIlIlIIIllIII; llllllllllllIIlllIlIIlIlIIIlllIl <= llllllllllllIIlllIlIIlIlIIIlIlIl; ++llllllllllllIIlllIlIIlIlIIIlllIl) {
                    for (int llllllllllllIIlllIlIIlIlIIIlllII = llllllllllllIIlllIlIIlIlIIIlIllI; llllllllllllIIlllIlIIlIlIIIlllII <= llllllllllllIIlllIlIIlIlIIlIIIII; ++llllllllllllIIlllIlIIlIlIIIlllII) {
                        if (!llllllllllllIIlllIlIIlIlIIIlllll || this.getBlockStateFromPos(llllllllllllIIlllIlIIlIlIIlIIlll, llllllllllllIIlllIlIIlIlIIIlllIl, llllllllllllIIlllIlIIlIlIIIllllI, llllllllllllIIlllIlIIlIlIIIlllII, llllllllllllIIlllIlIIlIlIIlIIllI).getMaterial() != Material.AIR) {
                            if (this.getYWithOffset(llllllllllllIIlllIlIIlIlIIIllllI) >= llllllllllllIIlllIlIIlIlIIlIIlll.getSeaLevel()) {
                                this.setBlockState(llllllllllllIIlllIlIIlIlIIlIIlll, Blocks.AIR.getDefaultState(), llllllllllllIIlllIlIIlIlIIIlllIl, llllllllllllIIlllIlIIlIlIIIllllI, llllllllllllIIlllIlIIlIlIIIlllII, llllllllllllIIlllIlIIlIlIIlIIllI);
                            }
                            else {
                                this.setBlockState(llllllllllllIIlllIlIIlIlIIlIIlll, Piece.WATER, llllllllllllIIlllIlIIlIlIIIlllIl, llllllllllllIIlllIlIIlIlIIIllllI, llllllllllllIIlllIlIIlIlIIIlllII, llllllllllllIIlllIlIIlIlIIlIIllI);
                            }
                        }
                    }
                }
            }
        }
        
        protected void generateDefaultFloor(final World llllllllllllIIlllIlIIlIlIIIIIlll, final StructureBoundingBox llllllllllllIIlllIlIIlIlIIIIIllI, final int llllllllllllIIlllIlIIlIlIIIIIlIl, final int llllllllllllIIlllIlIIlIIlllllllI, final boolean llllllllllllIIlllIlIIlIIllllllIl) {
            if (llllllllllllIIlllIlIIlIIllllllIl) {
                this.fillWithBlocks(llllllllllllIIlllIlIIlIlIIIIIlll, llllllllllllIIlllIlIIlIlIIIIIllI, llllllllllllIIlllIlIIlIlIIIIIlIl + 0, 0, llllllllllllIIlllIlIIlIIlllllllI + 0, llllllllllllIIlllIlIIlIlIIIIIlIl + 2, 0, llllllllllllIIlllIlIIlIIlllllllI + 8 - 1, Piece.ROUGH_PRISMARINE, Piece.ROUGH_PRISMARINE, false);
                this.fillWithBlocks(llllllllllllIIlllIlIIlIlIIIIIlll, llllllllllllIIlllIlIIlIlIIIIIllI, llllllllllllIIlllIlIIlIlIIIIIlIl + 5, 0, llllllllllllIIlllIlIIlIIlllllllI + 0, llllllllllllIIlllIlIIlIlIIIIIlIl + 8 - 1, 0, llllllllllllIIlllIlIIlIIlllllllI + 8 - 1, Piece.ROUGH_PRISMARINE, Piece.ROUGH_PRISMARINE, false);
                this.fillWithBlocks(llllllllllllIIlllIlIIlIlIIIIIlll, llllllllllllIIlllIlIIlIlIIIIIllI, llllllllllllIIlllIlIIlIlIIIIIlIl + 3, 0, llllllllllllIIlllIlIIlIIlllllllI + 0, llllllllllllIIlllIlIIlIlIIIIIlIl + 4, 0, llllllllllllIIlllIlIIlIIlllllllI + 2, Piece.ROUGH_PRISMARINE, Piece.ROUGH_PRISMARINE, false);
                this.fillWithBlocks(llllllllllllIIlllIlIIlIlIIIIIlll, llllllllllllIIlllIlIIlIlIIIIIllI, llllllllllllIIlllIlIIlIlIIIIIlIl + 3, 0, llllllllllllIIlllIlIIlIIlllllllI + 5, llllllllllllIIlllIlIIlIlIIIIIlIl + 4, 0, llllllllllllIIlllIlIIlIIlllllllI + 8 - 1, Piece.ROUGH_PRISMARINE, Piece.ROUGH_PRISMARINE, false);
                this.fillWithBlocks(llllllllllllIIlllIlIIlIlIIIIIlll, llllllllllllIIlllIlIIlIlIIIIIllI, llllllllllllIIlllIlIIlIlIIIIIlIl + 3, 0, llllllllllllIIlllIlIIlIIlllllllI + 2, llllllllllllIIlllIlIIlIlIIIIIlIl + 4, 0, llllllllllllIIlllIlIIlIIlllllllI + 2, Piece.BRICKS_PRISMARINE, Piece.BRICKS_PRISMARINE, false);
                this.fillWithBlocks(llllllllllllIIlllIlIIlIlIIIIIlll, llllllllllllIIlllIlIIlIlIIIIIllI, llllllllllllIIlllIlIIlIlIIIIIlIl + 3, 0, llllllllllllIIlllIlIIlIIlllllllI + 5, llllllllllllIIlllIlIIlIlIIIIIlIl + 4, 0, llllllllllllIIlllIlIIlIIlllllllI + 5, Piece.BRICKS_PRISMARINE, Piece.BRICKS_PRISMARINE, false);
                this.fillWithBlocks(llllllllllllIIlllIlIIlIlIIIIIlll, llllllllllllIIlllIlIIlIlIIIIIllI, llllllllllllIIlllIlIIlIlIIIIIlIl + 2, 0, llllllllllllIIlllIlIIlIIlllllllI + 3, llllllllllllIIlllIlIIlIlIIIIIlIl + 2, 0, llllllllllllIIlllIlIIlIIlllllllI + 4, Piece.BRICKS_PRISMARINE, Piece.BRICKS_PRISMARINE, false);
                this.fillWithBlocks(llllllllllllIIlllIlIIlIlIIIIIlll, llllllllllllIIlllIlIIlIlIIIIIllI, llllllllllllIIlllIlIIlIlIIIIIlIl + 5, 0, llllllllllllIIlllIlIIlIIlllllllI + 3, llllllllllllIIlllIlIIlIlIIIIIlIl + 5, 0, llllllllllllIIlllIlIIlIIlllllllI + 4, Piece.BRICKS_PRISMARINE, Piece.BRICKS_PRISMARINE, false);
            }
            else {
                this.fillWithBlocks(llllllllllllIIlllIlIIlIlIIIIIlll, llllllllllllIIlllIlIIlIlIIIIIllI, llllllllllllIIlllIlIIlIlIIIIIlIl + 0, 0, llllllllllllIIlllIlIIlIIlllllllI + 0, llllllllllllIIlllIlIIlIlIIIIIlIl + 8 - 1, 0, llllllllllllIIlllIlIIlIIlllllllI + 8 - 1, Piece.ROUGH_PRISMARINE, Piece.ROUGH_PRISMARINE, false);
            }
        }
        
        protected void generateBoxOnFillOnly(final World llllllllllllIIlllIlIIlIIlllIIIIl, final StructureBoundingBox llllllllllllIIlllIlIIlIIlllIIIII, final int llllllllllllIIlllIlIIlIIllIlllll, final int llllllllllllIIlllIlIIlIIllIllllI, final int llllllllllllIIlllIlIIlIIllIlllIl, final int llllllllllllIIlllIlIIlIIlllIlIIl, final int llllllllllllIIlllIlIIlIIlllIlIII, final int llllllllllllIIlllIlIIlIIlllIIlll, final IBlockState llllllllllllIIlllIlIIlIIlllIIllI) {
            for (int llllllllllllIIlllIlIIlIIlllIIlIl = llllllllllllIIlllIlIIlIIllIllllI; llllllllllllIIlllIlIIlIIlllIIlIl <= llllllllllllIIlllIlIIlIIlllIlIII; ++llllllllllllIIlllIlIIlIIlllIIlIl) {
                for (int llllllllllllIIlllIlIIlIIlllIIlII = llllllllllllIIlllIlIIlIIllIlllll; llllllllllllIIlllIlIIlIIlllIIlII <= llllllllllllIIlllIlIIlIIlllIlIIl; ++llllllllllllIIlllIlIIlIIlllIIlII) {
                    for (int llllllllllllIIlllIlIIlIIlllIIIll = llllllllllllIIlllIlIIlIIllIlllIl; llllllllllllIIlllIlIIlIIlllIIIll <= llllllllllllIIlllIlIIlIIlllIIlll; ++llllllllllllIIlllIlIIlIIlllIIIll) {
                        if (this.getBlockStateFromPos(llllllllllllIIlllIlIIlIIlllIIIIl, llllllllllllIIlllIlIIlIIlllIIlII, llllllllllllIIlllIlIIlIIlllIIlIl, llllllllllllIIlllIlIIlIIlllIIIll, llllllllllllIIlllIlIIlIIlllIIIII) == Piece.WATER) {
                            this.setBlockState(llllllllllllIIlllIlIIlIIlllIIIIl, llllllllllllIIlllIlIIlIIlllIIllI, llllllllllllIIlllIlIIlIIlllIIlII, llllllllllllIIlllIlIIlIIlllIIlIl, llllllllllllIIlllIlIIlIIlllIIIll, llllllllllllIIlllIlIIlIIlllIIIII);
                        }
                    }
                }
            }
        }
        
        protected static final int getRoomIndex(final int llllllllllllIIlllIlIIlIlIlllIIII, final int llllllllllllIIlllIlIIlIlIllIllll, final int llllllllllllIIlllIlIIlIlIlllIIIl) {
            return llllllllllllIIlllIlIIlIlIllIllll * 25 + llllllllllllIIlllIlIIlIlIlllIIIl * 5 + llllllllllllIIlllIlIIlIlIlllIIII;
        }
        
        public Piece(final EnumFacing llllllllllllIIlllIlIIlIlIllIIIII, final StructureBoundingBox llllllllllllIIlllIlIIlIlIlIlllII) {
            super(1);
            this.setCoordBaseMode(llllllllllllIIlllIlIIlIlIllIIIII);
            this.boundingBox = llllllllllllIIlllIlIIlIlIlIlllII;
        }
        
        static {
            ROUGH_PRISMARINE = Blocks.PRISMARINE.getStateFromMeta(BlockPrismarine.ROUGH_META);
            BRICKS_PRISMARINE = Blocks.PRISMARINE.getStateFromMeta(BlockPrismarine.BRICKS_META);
            DARK_PRISMARINE = Blocks.PRISMARINE.getStateFromMeta(BlockPrismarine.DARK_META);
            DOT_DECO_DATA = Piece.BRICKS_PRISMARINE;
            SEA_LANTERN = Blocks.SEA_LANTERN.getDefaultState();
            WATER = Blocks.WATER.getDefaultState();
            GRIDROOM_SOURCE_INDEX = getRoomIndex(2, 0, 0);
            GRIDROOM_TOP_CONNECT_INDEX = getRoomIndex(2, 2, 0);
            GRIDROOM_LEFTWING_CONNECT_INDEX = getRoomIndex(0, 1, 0);
            GRIDROOM_RIGHTWING_CONNECT_INDEX = getRoomIndex(4, 1, 0);
        }
        
        @Override
        protected void writeStructureToNBT(final NBTTagCompound llllllllllllIIlllIlIIlIlIIlllIIl) {
        }
        
        static /* synthetic */ int[] $SWITCH_TABLE$net$minecraft$util$EnumFacing() {
            final int[] $switch_TABLE$net$minecraft$util$EnumFacing = Piece.$SWITCH_TABLE$net$minecraft$util$EnumFacing;
            if ($switch_TABLE$net$minecraft$util$EnumFacing != null) {
                return $switch_TABLE$net$minecraft$util$EnumFacing;
            }
            final short llllllllllllIIlllIlIIlIIlIIllIII = (Object)new int[EnumFacing.values().length];
            try {
                llllllllllllIIlllIlIIlIIlIIllIII[EnumFacing.DOWN.ordinal()] = true;
            }
            catch (NoSuchFieldError noSuchFieldError) {}
            try {
                llllllllllllIIlllIlIIlIIlIIllIII[EnumFacing.EAST.ordinal()] = 6;
            }
            catch (NoSuchFieldError noSuchFieldError2) {}
            try {
                llllllllllllIIlllIlIIlIIlIIllIII[EnumFacing.NORTH.ordinal()] = 3;
            }
            catch (NoSuchFieldError noSuchFieldError3) {}
            try {
                llllllllllllIIlllIlIIlIIlIIllIII[EnumFacing.SOUTH.ordinal()] = 4;
            }
            catch (NoSuchFieldError noSuchFieldError4) {}
            try {
                llllllllllllIIlllIlIIlIIlIIllIII[EnumFacing.UP.ordinal()] = 2;
            }
            catch (NoSuchFieldError noSuchFieldError5) {}
            try {
                llllllllllllIIlllIlIIlIIlIIllIII[EnumFacing.WEST.ordinal()] = 5;
            }
            catch (NoSuchFieldError noSuchFieldError6) {}
            return Piece.$SWITCH_TABLE$net$minecraft$util$EnumFacing = (int[])(Object)llllllllllllIIlllIlIIlIIlIIllIII;
        }
        
        protected Piece(final int llllllllllllIIlllIlIIlIlIlIIllll, final EnumFacing llllllllllllIIlllIlIIlIlIlIIIIll, final RoomDefinition llllllllllllIIlllIlIIlIlIlIIIIlI, final int llllllllllllIIlllIlIIlIlIlIIIIIl, final int llllllllllllIIlllIlIIlIlIlIIIIII, final int llllllllllllIIlllIlIIlIlIIllllll) {
            super(llllllllllllIIlllIlIIlIlIlIIllll);
            this.setCoordBaseMode(llllllllllllIIlllIlIIlIlIlIIIIll);
            this.roomDefinition = llllllllllllIIlllIlIIlIlIlIIIIlI;
            final int llllllllllllIIlllIlIIlIlIlIIlIIl = llllllllllllIIlllIlIIlIlIlIIIIlI.index;
            final int llllllllllllIIlllIlIIlIlIlIIlIII = llllllllllllIIlllIlIIlIlIlIIlIIl % 5;
            final int llllllllllllIIlllIlIIlIlIlIIIlll = llllllllllllIIlllIlIIlIlIlIIlIIl / 5 % 5;
            final int llllllllllllIIlllIlIIlIlIlIIIllI = llllllllllllIIlllIlIIlIlIlIIlIIl / 25;
            if (llllllllllllIIlllIlIIlIlIlIIIIll != EnumFacing.NORTH && llllllllllllIIlllIlIIlIlIlIIIIll != EnumFacing.SOUTH) {
                this.boundingBox = new StructureBoundingBox(0, 0, 0, llllllllllllIIlllIlIIlIlIIllllll * 8 - 1, llllllllllllIIlllIlIIlIlIlIIIIII * 4 - 1, llllllllllllIIlllIlIIlIlIlIIIIIl * 8 - 1);
            }
            else {
                this.boundingBox = new StructureBoundingBox(0, 0, 0, llllllllllllIIlllIlIIlIlIlIIIIIl * 8 - 1, llllllllllllIIlllIlIIlIlIlIIIIII * 4 - 1, llllllllllllIIlllIlIIlIlIIllllll * 8 - 1);
            }
            switch ($SWITCH_TABLE$net$minecraft$util$EnumFacing()[llllllllllllIIlllIlIIlIlIlIIIIll.ordinal()]) {
                case 3: {
                    this.boundingBox.offset(llllllllllllIIlllIlIIlIlIlIIlIII * 8, llllllllllllIIlllIlIIlIlIlIIIllI * 4, -(llllllllllllIIlllIlIIlIlIlIIIlll + llllllllllllIIlllIlIIlIlIIllllll) * 8 + 1);
                    break;
                }
                case 4: {
                    this.boundingBox.offset(llllllllllllIIlllIlIIlIlIlIIlIII * 8, llllllllllllIIlllIlIIlIlIlIIIllI * 4, llllllllllllIIlllIlIIlIlIlIIIlll * 8);
                    break;
                }
                case 5: {
                    this.boundingBox.offset(-(llllllllllllIIlllIlIIlIlIlIIIlll + llllllllllllIIlllIlIIlIlIIllllll) * 8 + 1, llllllllllllIIlllIlIIlIlIlIIIllI * 4, llllllllllllIIlllIlIIlIlIlIIlIII * 8);
                    break;
                }
                default: {
                    this.boundingBox.offset(llllllllllllIIlllIlIIlIlIlIIIlll * 8, llllllllllllIIlllIlIIlIlIlIIIllI * 4, llllllllllllIIlllIlIIlIlIlIIlIII * 8);
                    break;
                }
            }
        }
        
        public Piece() {
            super(0);
        }
        
        protected boolean doesChunkIntersect(final StructureBoundingBox llllllllllllIIlllIlIIlIIllIIlIlI, final int llllllllllllIIlllIlIIlIIlIllllll, final int llllllllllllIIlllIlIIlIIllIIlIII, final int llllllllllllIIlllIlIIlIIllIIIlll, final int llllllllllllIIlllIlIIlIIllIIIllI) {
            final int llllllllllllIIlllIlIIlIIllIIIlIl = this.getXWithOffset(llllllllllllIIlllIlIIlIIlIllllll, llllllllllllIIlllIlIIlIIllIIlIII);
            final int llllllllllllIIlllIlIIlIIllIIIlII = this.getZWithOffset(llllllllllllIIlllIlIIlIIlIllllll, llllllllllllIIlllIlIIlIIllIIlIII);
            final int llllllllllllIIlllIlIIlIIllIIIIll = this.getXWithOffset(llllllllllllIIlllIlIIlIIllIIIlll, llllllllllllIIlllIlIIlIIllIIIllI);
            final int llllllllllllIIlllIlIIlIIllIIIIlI = this.getZWithOffset(llllllllllllIIlllIlIIlIIllIIIlll, llllllllllllIIlllIlIIlIIllIIIllI);
            return llllllllllllIIlllIlIIlIIllIIlIlI.intersectsWith(Math.min(llllllllllllIIlllIlIIlIIllIIIlIl, llllllllllllIIlllIlIIlIIllIIIIll), Math.min(llllllllllllIIlllIlIIlIIllIIIlII, llllllllllllIIlllIlIIlIIllIIIIlI), Math.max(llllllllllllIIlllIlIIlIIllIIIlIl, llllllllllllIIlllIlIIlIIllIIIIll), Math.max(llllllllllllIIlllIlIIlIIllIIIlII, llllllllllllIIlllIlIIlIIllIIIIlI));
        }
        
        public Piece(final int llllllllllllIIlllIlIIlIlIllIIlll) {
            super(llllllllllllIIlllIlIIlIlIllIIlll);
        }
    }
    
    static class RoomDefinition
    {
        /* synthetic */ boolean isSource;
        /* synthetic */ boolean claimed;
        /* synthetic */ int scanIndex;
        /* synthetic */ boolean[] hasOpening;
        /* synthetic */ RoomDefinition[] connections;
        /* synthetic */ int index;
        
        public int countOpenings() {
            int lllllllllllllllIllIlllIIlllIlIlI = 0;
            for (int lllllllllllllllIllIlllIIlllIlIIl = 0; lllllllllllllllIllIlllIIlllIlIIl < 6; ++lllllllllllllllIllIlllIIlllIlIIl) {
                if (this.hasOpening[lllllllllllllllIllIlllIIlllIlIIl]) {
                    ++lllllllllllllllIllIlllIIlllIlIlI;
                }
            }
            return lllllllllllllllIllIlllIIlllIlIlI;
        }
        
        public boolean findSource(final int lllllllllllllllIllIlllIIllllIllI) {
            if (this.isSource) {
                return true;
            }
            this.scanIndex = lllllllllllllllIllIlllIIllllIllI;
            for (int lllllllllllllllIllIlllIIllllIlIl = 0; lllllllllllllllIllIlllIIllllIlIl < 6; ++lllllllllllllllIllIlllIIllllIlIl) {
                if (this.connections[lllllllllllllllIllIlllIIllllIlIl] != null && this.hasOpening[lllllllllllllllIllIlllIIllllIlIl] && this.connections[lllllllllllllllIllIlllIIllllIlIl].scanIndex != lllllllllllllllIllIlllIIllllIllI && this.connections[lllllllllllllllIllIlllIIllllIlIl].findSource(lllllllllllllllIllIlllIIllllIllI)) {
                    return true;
                }
            }
            return false;
        }
        
        public RoomDefinition(final int lllllllllllllllIllIlllIlIIIIlIlI) {
            this.connections = new RoomDefinition[6];
            this.hasOpening = new boolean[6];
            this.index = lllllllllllllllIllIlllIlIIIIlIlI;
        }
        
        public boolean isSpecial() {
            return this.index >= 75;
        }
        
        public void updateOpenings() {
            for (int lllllllllllllllIllIlllIIllllllIl = 0; lllllllllllllllIllIlllIIllllllIl < 6; ++lllllllllllllllIllIlllIIllllllIl) {
                this.hasOpening[lllllllllllllllIllIlllIIllllllIl] = (this.connections[lllllllllllllllIllIlllIIllllllIl] != null);
            }
        }
        
        public void setConnection(final EnumFacing lllllllllllllllIllIlllIlIIIIIlIl, final RoomDefinition lllllllllllllllIllIlllIlIIIIIIIl) {
            this.connections[lllllllllllllllIllIlllIlIIIIIlIl.getIndex()] = lllllllllllllllIllIlllIlIIIIIIIl;
            lllllllllllllllIllIlllIlIIIIIIIl.connections[lllllllllllllllIllIlllIlIIIIIlIl.getOpposite().getIndex()] = this;
        }
    }
    
    interface MonumentRoomFitHelper
    {
        Piece create(final EnumFacing p0, final RoomDefinition p1, final Random p2);
        
        boolean fits(final RoomDefinition p0);
    }
    
    public static class DoubleYZRoom extends Piece
    {
        public DoubleYZRoom() {
        }
        
        public DoubleYZRoom(final EnumFacing lllllllllllIIIllIlIIIllIIlIIlIII, final RoomDefinition lllllllllllIIIllIlIIIllIIlIIIlll, final Random lllllllllllIIIllIlIIIllIIlIIIllI) {
            super(1, lllllllllllIIIllIlIIIllIIlIIlIII, lllllllllllIIIllIlIIIllIIlIIIlll, 1, 2, 2);
        }
        
        @Override
        public boolean addComponentParts(final World lllllllllllIIIllIlIIIllIIIlllIII, final Random lllllllllllIIIllIlIIIllIIIllIlll, final StructureBoundingBox lllllllllllIIIllIlIIIllIIIlIlIll) {
            final RoomDefinition lllllllllllIIIllIlIIIllIIIllIlIl = this.roomDefinition.connections[EnumFacing.NORTH.getIndex()];
            final RoomDefinition lllllllllllIIIllIlIIIllIIIllIlII = this.roomDefinition;
            final RoomDefinition lllllllllllIIIllIlIIIllIIIllIIll = lllllllllllIIIllIlIIIllIIIllIlIl.connections[EnumFacing.UP.getIndex()];
            final RoomDefinition lllllllllllIIIllIlIIIllIIIllIIlI = lllllllllllIIIllIlIIIllIIIllIlII.connections[EnumFacing.UP.getIndex()];
            if (this.roomDefinition.index / 25 > 0) {
                this.generateDefaultFloor(lllllllllllIIIllIlIIIllIIIlllIII, lllllllllllIIIllIlIIIllIIIlIlIll, 0, 8, lllllllllllIIIllIlIIIllIIIllIlIl.hasOpening[EnumFacing.DOWN.getIndex()]);
                this.generateDefaultFloor(lllllllllllIIIllIlIIIllIIIlllIII, lllllllllllIIIllIlIIIllIIIlIlIll, 0, 0, lllllllllllIIIllIlIIIllIIIllIlII.hasOpening[EnumFacing.DOWN.getIndex()]);
            }
            if (lllllllllllIIIllIlIIIllIIIllIIlI.connections[EnumFacing.UP.getIndex()] == null) {
                this.generateBoxOnFillOnly(lllllllllllIIIllIlIIIllIIIlllIII, lllllllllllIIIllIlIIIllIIIlIlIll, 1, 8, 1, 6, 8, 7, DoubleYZRoom.ROUGH_PRISMARINE);
            }
            if (lllllllllllIIIllIlIIIllIIIllIIll.connections[EnumFacing.UP.getIndex()] == null) {
                this.generateBoxOnFillOnly(lllllllllllIIIllIlIIIllIIIlllIII, lllllllllllIIIllIlIIIllIIIlIlIll, 1, 8, 8, 6, 8, 14, DoubleYZRoom.ROUGH_PRISMARINE);
            }
            for (int lllllllllllIIIllIlIIIllIIIllIIIl = 1; lllllllllllIIIllIlIIIllIIIllIIIl <= 7; ++lllllllllllIIIllIlIIIllIIIllIIIl) {
                IBlockState lllllllllllIIIllIlIIIllIIIllIIII = DoubleYZRoom.BRICKS_PRISMARINE;
                if (lllllllllllIIIllIlIIIllIIIllIIIl == 2 || lllllllllllIIIllIlIIIllIIIllIIIl == 6) {
                    lllllllllllIIIllIlIIIllIIIllIIII = DoubleYZRoom.ROUGH_PRISMARINE;
                }
                this.fillWithBlocks(lllllllllllIIIllIlIIIllIIIlllIII, lllllllllllIIIllIlIIIllIIIlIlIll, 0, lllllllllllIIIllIlIIIllIIIllIIIl, 0, 0, lllllllllllIIIllIlIIIllIIIllIIIl, 15, lllllllllllIIIllIlIIIllIIIllIIII, lllllllllllIIIllIlIIIllIIIllIIII, false);
                this.fillWithBlocks(lllllllllllIIIllIlIIIllIIIlllIII, lllllllllllIIIllIlIIIllIIIlIlIll, 7, lllllllllllIIIllIlIIIllIIIllIIIl, 0, 7, lllllllllllIIIllIlIIIllIIIllIIIl, 15, lllllllllllIIIllIlIIIllIIIllIIII, lllllllllllIIIllIlIIIllIIIllIIII, false);
                this.fillWithBlocks(lllllllllllIIIllIlIIIllIIIlllIII, lllllllllllIIIllIlIIIllIIIlIlIll, 1, lllllllllllIIIllIlIIIllIIIllIIIl, 0, 6, lllllllllllIIIllIlIIIllIIIllIIIl, 0, lllllllllllIIIllIlIIIllIIIllIIII, lllllllllllIIIllIlIIIllIIIllIIII, false);
                this.fillWithBlocks(lllllllllllIIIllIlIIIllIIIlllIII, lllllllllllIIIllIlIIIllIIIlIlIll, 1, lllllllllllIIIllIlIIIllIIIllIIIl, 15, 6, lllllllllllIIIllIlIIIllIIIllIIIl, 15, lllllllllllIIIllIlIIIllIIIllIIII, lllllllllllIIIllIlIIIllIIIllIIII, false);
            }
            for (int lllllllllllIIIllIlIIIllIIIlIllll = 1; lllllllllllIIIllIlIIIllIIIlIllll <= 7; ++lllllllllllIIIllIlIIIllIIIlIllll) {
                IBlockState lllllllllllIIIllIlIIIllIIIlIlllI = DoubleYZRoom.DARK_PRISMARINE;
                if (lllllllllllIIIllIlIIIllIIIlIllll == 2 || lllllllllllIIIllIlIIIllIIIlIllll == 6) {
                    lllllllllllIIIllIlIIIllIIIlIlllI = DoubleYZRoom.SEA_LANTERN;
                }
                this.fillWithBlocks(lllllllllllIIIllIlIIIllIIIlllIII, lllllllllllIIIllIlIIIllIIIlIlIll, 3, lllllllllllIIIllIlIIIllIIIlIllll, 7, 4, lllllllllllIIIllIlIIIllIIIlIllll, 8, lllllllllllIIIllIlIIIllIIIlIlllI, lllllllllllIIIllIlIIIllIIIlIlllI, false);
            }
            if (lllllllllllIIIllIlIIIllIIIllIlII.hasOpening[EnumFacing.SOUTH.getIndex()]) {
                this.generateWaterBox(lllllllllllIIIllIlIIIllIIIlllIII, lllllllllllIIIllIlIIIllIIIlIlIll, 3, 1, 0, 4, 2, 0, false);
            }
            if (lllllllllllIIIllIlIIIllIIIllIlII.hasOpening[EnumFacing.EAST.getIndex()]) {
                this.generateWaterBox(lllllllllllIIIllIlIIIllIIIlllIII, lllllllllllIIIllIlIIIllIIIlIlIll, 7, 1, 3, 7, 2, 4, false);
            }
            if (lllllllllllIIIllIlIIIllIIIllIlII.hasOpening[EnumFacing.WEST.getIndex()]) {
                this.generateWaterBox(lllllllllllIIIllIlIIIllIIIlllIII, lllllllllllIIIllIlIIIllIIIlIlIll, 0, 1, 3, 0, 2, 4, false);
            }
            if (lllllllllllIIIllIlIIIllIIIllIlIl.hasOpening[EnumFacing.NORTH.getIndex()]) {
                this.generateWaterBox(lllllllllllIIIllIlIIIllIIIlllIII, lllllllllllIIIllIlIIIllIIIlIlIll, 3, 1, 15, 4, 2, 15, false);
            }
            if (lllllllllllIIIllIlIIIllIIIllIlIl.hasOpening[EnumFacing.WEST.getIndex()]) {
                this.generateWaterBox(lllllllllllIIIllIlIIIllIIIlllIII, lllllllllllIIIllIlIIIllIIIlIlIll, 0, 1, 11, 0, 2, 12, false);
            }
            if (lllllllllllIIIllIlIIIllIIIllIlIl.hasOpening[EnumFacing.EAST.getIndex()]) {
                this.generateWaterBox(lllllllllllIIIllIlIIIllIIIlllIII, lllllllllllIIIllIlIIIllIIIlIlIll, 7, 1, 11, 7, 2, 12, false);
            }
            if (lllllllllllIIIllIlIIIllIIIllIIlI.hasOpening[EnumFacing.SOUTH.getIndex()]) {
                this.generateWaterBox(lllllllllllIIIllIlIIIllIIIlllIII, lllllllllllIIIllIlIIIllIIIlIlIll, 3, 5, 0, 4, 6, 0, false);
            }
            if (lllllllllllIIIllIlIIIllIIIllIIlI.hasOpening[EnumFacing.EAST.getIndex()]) {
                this.generateWaterBox(lllllllllllIIIllIlIIIllIIIlllIII, lllllllllllIIIllIlIIIllIIIlIlIll, 7, 5, 3, 7, 6, 4, false);
                this.fillWithBlocks(lllllllllllIIIllIlIIIllIIIlllIII, lllllllllllIIIllIlIIIllIIIlIlIll, 5, 4, 2, 6, 4, 5, DoubleYZRoom.BRICKS_PRISMARINE, DoubleYZRoom.BRICKS_PRISMARINE, false);
                this.fillWithBlocks(lllllllllllIIIllIlIIIllIIIlllIII, lllllllllllIIIllIlIIIllIIIlIlIll, 6, 1, 2, 6, 3, 2, DoubleYZRoom.BRICKS_PRISMARINE, DoubleYZRoom.BRICKS_PRISMARINE, false);
                this.fillWithBlocks(lllllllllllIIIllIlIIIllIIIlllIII, lllllllllllIIIllIlIIIllIIIlIlIll, 6, 1, 5, 6, 3, 5, DoubleYZRoom.BRICKS_PRISMARINE, DoubleYZRoom.BRICKS_PRISMARINE, false);
            }
            if (lllllllllllIIIllIlIIIllIIIllIIlI.hasOpening[EnumFacing.WEST.getIndex()]) {
                this.generateWaterBox(lllllllllllIIIllIlIIIllIIIlllIII, lllllllllllIIIllIlIIIllIIIlIlIll, 0, 5, 3, 0, 6, 4, false);
                this.fillWithBlocks(lllllllllllIIIllIlIIIllIIIlllIII, lllllllllllIIIllIlIIIllIIIlIlIll, 1, 4, 2, 2, 4, 5, DoubleYZRoom.BRICKS_PRISMARINE, DoubleYZRoom.BRICKS_PRISMARINE, false);
                this.fillWithBlocks(lllllllllllIIIllIlIIIllIIIlllIII, lllllllllllIIIllIlIIIllIIIlIlIll, 1, 1, 2, 1, 3, 2, DoubleYZRoom.BRICKS_PRISMARINE, DoubleYZRoom.BRICKS_PRISMARINE, false);
                this.fillWithBlocks(lllllllllllIIIllIlIIIllIIIlllIII, lllllllllllIIIllIlIIIllIIIlIlIll, 1, 1, 5, 1, 3, 5, DoubleYZRoom.BRICKS_PRISMARINE, DoubleYZRoom.BRICKS_PRISMARINE, false);
            }
            if (lllllllllllIIIllIlIIIllIIIllIIll.hasOpening[EnumFacing.NORTH.getIndex()]) {
                this.generateWaterBox(lllllllllllIIIllIlIIIllIIIlllIII, lllllllllllIIIllIlIIIllIIIlIlIll, 3, 5, 15, 4, 6, 15, false);
            }
            if (lllllllllllIIIllIlIIIllIIIllIIll.hasOpening[EnumFacing.WEST.getIndex()]) {
                this.generateWaterBox(lllllllllllIIIllIlIIIllIIIlllIII, lllllllllllIIIllIlIIIllIIIlIlIll, 0, 5, 11, 0, 6, 12, false);
                this.fillWithBlocks(lllllllllllIIIllIlIIIllIIIlllIII, lllllllllllIIIllIlIIIllIIIlIlIll, 1, 4, 10, 2, 4, 13, DoubleYZRoom.BRICKS_PRISMARINE, DoubleYZRoom.BRICKS_PRISMARINE, false);
                this.fillWithBlocks(lllllllllllIIIllIlIIIllIIIlllIII, lllllllllllIIIllIlIIIllIIIlIlIll, 1, 1, 10, 1, 3, 10, DoubleYZRoom.BRICKS_PRISMARINE, DoubleYZRoom.BRICKS_PRISMARINE, false);
                this.fillWithBlocks(lllllllllllIIIllIlIIIllIIIlllIII, lllllllllllIIIllIlIIIllIIIlIlIll, 1, 1, 13, 1, 3, 13, DoubleYZRoom.BRICKS_PRISMARINE, DoubleYZRoom.BRICKS_PRISMARINE, false);
            }
            if (lllllllllllIIIllIlIIIllIIIllIIll.hasOpening[EnumFacing.EAST.getIndex()]) {
                this.generateWaterBox(lllllllllllIIIllIlIIIllIIIlllIII, lllllllllllIIIllIlIIIllIIIlIlIll, 7, 5, 11, 7, 6, 12, false);
                this.fillWithBlocks(lllllllllllIIIllIlIIIllIIIlllIII, lllllllllllIIIllIlIIIllIIIlIlIll, 5, 4, 10, 6, 4, 13, DoubleYZRoom.BRICKS_PRISMARINE, DoubleYZRoom.BRICKS_PRISMARINE, false);
                this.fillWithBlocks(lllllllllllIIIllIlIIIllIIIlllIII, lllllllllllIIIllIlIIIllIIIlIlIll, 6, 1, 10, 6, 3, 10, DoubleYZRoom.BRICKS_PRISMARINE, DoubleYZRoom.BRICKS_PRISMARINE, false);
                this.fillWithBlocks(lllllllllllIIIllIlIIIllIIIlllIII, lllllllllllIIIllIlIIIllIIIlIlIll, 6, 1, 13, 6, 3, 13, DoubleYZRoom.BRICKS_PRISMARINE, DoubleYZRoom.BRICKS_PRISMARINE, false);
            }
            return true;
        }
    }
    
    public static class SimpleTopRoom extends Piece
    {
        public SimpleTopRoom() {
        }
        
        public SimpleTopRoom(final EnumFacing lllllllllllIllIlIlIlllIlllllllIl, final RoomDefinition lllllllllllIllIlIlIlllIlllllllII, final Random lllllllllllIllIlIlIlllIllllllIll) {
            super(1, lllllllllllIllIlIlIlllIlllllllIl, lllllllllllIllIlIlIlllIlllllllII, 1, 1, 1);
        }
        
        @Override
        public boolean addComponentParts(final World lllllllllllIllIlIlIlllIllllIlIII, final Random lllllllllllIllIlIlIlllIllllIlllI, final StructureBoundingBox lllllllllllIllIlIlIlllIllllIllIl) {
            if (this.roomDefinition.index / 25 > 0) {
                this.generateDefaultFloor(lllllllllllIllIlIlIlllIllllIlIII, lllllllllllIllIlIlIlllIllllIllIl, 0, 0, this.roomDefinition.hasOpening[EnumFacing.DOWN.getIndex()]);
            }
            if (this.roomDefinition.connections[EnumFacing.UP.getIndex()] == null) {
                this.generateBoxOnFillOnly(lllllllllllIllIlIlIlllIllllIlIII, lllllllllllIllIlIlIlllIllllIllIl, 1, 4, 1, 6, 4, 6, SimpleTopRoom.ROUGH_PRISMARINE);
            }
            for (int lllllllllllIllIlIlIlllIllllIllII = 1; lllllllllllIllIlIlIlllIllllIllII <= 6; ++lllllllllllIllIlIlIlllIllllIllII) {
                for (int lllllllllllIllIlIlIlllIllllIlIll = 1; lllllllllllIllIlIlIlllIllllIlIll <= 6; ++lllllllllllIllIlIlIlllIllllIlIll) {
                    if (lllllllllllIllIlIlIlllIllllIlllI.nextInt(3) != 0) {
                        final int lllllllllllIllIlIlIlllIllllIlIlI = 2 + ((lllllllllllIllIlIlIlllIllllIlllI.nextInt(4) != 0) ? 1 : 0);
                        this.fillWithBlocks(lllllllllllIllIlIlIlllIllllIlIII, lllllllllllIllIlIlIlllIllllIllIl, lllllllllllIllIlIlIlllIllllIllII, lllllllllllIllIlIlIlllIllllIlIlI, lllllllllllIllIlIlIlllIllllIlIll, lllllllllllIllIlIlIlllIllllIllII, 3, lllllllllllIllIlIlIlllIllllIlIll, Blocks.SPONGE.getStateFromMeta(1), Blocks.SPONGE.getStateFromMeta(1), false);
                    }
                }
            }
            this.fillWithBlocks(lllllllllllIllIlIlIlllIllllIlIII, lllllllllllIllIlIlIlllIllllIllIl, 0, 1, 0, 0, 1, 7, SimpleTopRoom.BRICKS_PRISMARINE, SimpleTopRoom.BRICKS_PRISMARINE, false);
            this.fillWithBlocks(lllllllllllIllIlIlIlllIllllIlIII, lllllllllllIllIlIlIlllIllllIllIl, 7, 1, 0, 7, 1, 7, SimpleTopRoom.BRICKS_PRISMARINE, SimpleTopRoom.BRICKS_PRISMARINE, false);
            this.fillWithBlocks(lllllllllllIllIlIlIlllIllllIlIII, lllllllllllIllIlIlIlllIllllIllIl, 1, 1, 0, 6, 1, 0, SimpleTopRoom.BRICKS_PRISMARINE, SimpleTopRoom.BRICKS_PRISMARINE, false);
            this.fillWithBlocks(lllllllllllIllIlIlIlllIllllIlIII, lllllllllllIllIlIlIlllIllllIllIl, 1, 1, 7, 6, 1, 7, SimpleTopRoom.BRICKS_PRISMARINE, SimpleTopRoom.BRICKS_PRISMARINE, false);
            this.fillWithBlocks(lllllllllllIllIlIlIlllIllllIlIII, lllllllllllIllIlIlIlllIllllIllIl, 0, 2, 0, 0, 2, 7, SimpleTopRoom.DARK_PRISMARINE, SimpleTopRoom.DARK_PRISMARINE, false);
            this.fillWithBlocks(lllllllllllIllIlIlIlllIllllIlIII, lllllllllllIllIlIlIlllIllllIllIl, 7, 2, 0, 7, 2, 7, SimpleTopRoom.DARK_PRISMARINE, SimpleTopRoom.DARK_PRISMARINE, false);
            this.fillWithBlocks(lllllllllllIllIlIlIlllIllllIlIII, lllllllllllIllIlIlIlllIllllIllIl, 1, 2, 0, 6, 2, 0, SimpleTopRoom.DARK_PRISMARINE, SimpleTopRoom.DARK_PRISMARINE, false);
            this.fillWithBlocks(lllllllllllIllIlIlIlllIllllIlIII, lllllllllllIllIlIlIlllIllllIllIl, 1, 2, 7, 6, 2, 7, SimpleTopRoom.DARK_PRISMARINE, SimpleTopRoom.DARK_PRISMARINE, false);
            this.fillWithBlocks(lllllllllllIllIlIlIlllIllllIlIII, lllllllllllIllIlIlIlllIllllIllIl, 0, 3, 0, 0, 3, 7, SimpleTopRoom.BRICKS_PRISMARINE, SimpleTopRoom.BRICKS_PRISMARINE, false);
            this.fillWithBlocks(lllllllllllIllIlIlIlllIllllIlIII, lllllllllllIllIlIlIlllIllllIllIl, 7, 3, 0, 7, 3, 7, SimpleTopRoom.BRICKS_PRISMARINE, SimpleTopRoom.BRICKS_PRISMARINE, false);
            this.fillWithBlocks(lllllllllllIllIlIlIlllIllllIlIII, lllllllllllIllIlIlIlllIllllIllIl, 1, 3, 0, 6, 3, 0, SimpleTopRoom.BRICKS_PRISMARINE, SimpleTopRoom.BRICKS_PRISMARINE, false);
            this.fillWithBlocks(lllllllllllIllIlIlIlllIllllIlIII, lllllllllllIllIlIlIlllIllllIllIl, 1, 3, 7, 6, 3, 7, SimpleTopRoom.BRICKS_PRISMARINE, SimpleTopRoom.BRICKS_PRISMARINE, false);
            this.fillWithBlocks(lllllllllllIllIlIlIlllIllllIlIII, lllllllllllIllIlIlIlllIllllIllIl, 0, 1, 3, 0, 2, 4, SimpleTopRoom.DARK_PRISMARINE, SimpleTopRoom.DARK_PRISMARINE, false);
            this.fillWithBlocks(lllllllllllIllIlIlIlllIllllIlIII, lllllllllllIllIlIlIlllIllllIllIl, 7, 1, 3, 7, 2, 4, SimpleTopRoom.DARK_PRISMARINE, SimpleTopRoom.DARK_PRISMARINE, false);
            this.fillWithBlocks(lllllllllllIllIlIlIlllIllllIlIII, lllllllllllIllIlIlIlllIllllIllIl, 3, 1, 0, 4, 2, 0, SimpleTopRoom.DARK_PRISMARINE, SimpleTopRoom.DARK_PRISMARINE, false);
            this.fillWithBlocks(lllllllllllIllIlIlIlllIllllIlIII, lllllllllllIllIlIlIlllIllllIllIl, 3, 1, 7, 4, 2, 7, SimpleTopRoom.DARK_PRISMARINE, SimpleTopRoom.DARK_PRISMARINE, false);
            if (this.roomDefinition.hasOpening[EnumFacing.SOUTH.getIndex()]) {
                this.generateWaterBox(lllllllllllIllIlIlIlllIllllIlIII, lllllllllllIllIlIlIlllIllllIllIl, 3, 1, 0, 4, 2, 0, false);
            }
            return true;
        }
    }
    
    public static class Penthouse extends Piece
    {
        public Penthouse(final EnumFacing llllllllllllIIlIIIIlIIlllIIIlllI, final StructureBoundingBox llllllllllllIIlIIIIlIIlllIIlIIII) {
            super(llllllllllllIIlIIIIlIIlllIIIlllI, llllllllllllIIlIIIIlIIlllIIlIIII);
        }
        
        @Override
        public boolean addComponentParts(final World llllllllllllIIlIIIIlIIllIlllllIl, final Random llllllllllllIIlIIIIlIIlllIIIIlII, final StructureBoundingBox llllllllllllIIlIIIIlIIllIlllllII) {
            this.fillWithBlocks(llllllllllllIIlIIIIlIIllIlllllIl, llllllllllllIIlIIIIlIIllIlllllII, 2, -1, 2, 11, -1, 11, Penthouse.BRICKS_PRISMARINE, Penthouse.BRICKS_PRISMARINE, false);
            this.fillWithBlocks(llllllllllllIIlIIIIlIIllIlllllIl, llllllllllllIIlIIIIlIIllIlllllII, 0, -1, 0, 1, -1, 11, Penthouse.ROUGH_PRISMARINE, Penthouse.ROUGH_PRISMARINE, false);
            this.fillWithBlocks(llllllllllllIIlIIIIlIIllIlllllIl, llllllllllllIIlIIIIlIIllIlllllII, 12, -1, 0, 13, -1, 11, Penthouse.ROUGH_PRISMARINE, Penthouse.ROUGH_PRISMARINE, false);
            this.fillWithBlocks(llllllllllllIIlIIIIlIIllIlllllIl, llllllllllllIIlIIIIlIIllIlllllII, 2, -1, 0, 11, -1, 1, Penthouse.ROUGH_PRISMARINE, Penthouse.ROUGH_PRISMARINE, false);
            this.fillWithBlocks(llllllllllllIIlIIIIlIIllIlllllIl, llllllllllllIIlIIIIlIIllIlllllII, 2, -1, 12, 11, -1, 13, Penthouse.ROUGH_PRISMARINE, Penthouse.ROUGH_PRISMARINE, false);
            this.fillWithBlocks(llllllllllllIIlIIIIlIIllIlllllIl, llllllllllllIIlIIIIlIIllIlllllII, 0, 0, 0, 0, 0, 13, Penthouse.BRICKS_PRISMARINE, Penthouse.BRICKS_PRISMARINE, false);
            this.fillWithBlocks(llllllllllllIIlIIIIlIIllIlllllIl, llllllllllllIIlIIIIlIIllIlllllII, 13, 0, 0, 13, 0, 13, Penthouse.BRICKS_PRISMARINE, Penthouse.BRICKS_PRISMARINE, false);
            this.fillWithBlocks(llllllllllllIIlIIIIlIIllIlllllIl, llllllllllllIIlIIIIlIIllIlllllII, 1, 0, 0, 12, 0, 0, Penthouse.BRICKS_PRISMARINE, Penthouse.BRICKS_PRISMARINE, false);
            this.fillWithBlocks(llllllllllllIIlIIIIlIIllIlllllIl, llllllllllllIIlIIIIlIIllIlllllII, 1, 0, 13, 12, 0, 13, Penthouse.BRICKS_PRISMARINE, Penthouse.BRICKS_PRISMARINE, false);
            for (int llllllllllllIIlIIIIlIIlllIIIIIlI = 2; llllllllllllIIlIIIIlIIlllIIIIIlI <= 11; llllllllllllIIlIIIIlIIlllIIIIIlI += 3) {
                this.setBlockState(llllllllllllIIlIIIIlIIllIlllllIl, Penthouse.SEA_LANTERN, 0, 0, llllllllllllIIlIIIIlIIlllIIIIIlI, llllllllllllIIlIIIIlIIllIlllllII);
                this.setBlockState(llllllllllllIIlIIIIlIIllIlllllIl, Penthouse.SEA_LANTERN, 13, 0, llllllllllllIIlIIIIlIIlllIIIIIlI, llllllllllllIIlIIIIlIIllIlllllII);
                this.setBlockState(llllllllllllIIlIIIIlIIllIlllllIl, Penthouse.SEA_LANTERN, llllllllllllIIlIIIIlIIlllIIIIIlI, 0, 0, llllllllllllIIlIIIIlIIllIlllllII);
            }
            this.fillWithBlocks(llllllllllllIIlIIIIlIIllIlllllIl, llllllllllllIIlIIIIlIIllIlllllII, 2, 0, 3, 4, 0, 9, Penthouse.BRICKS_PRISMARINE, Penthouse.BRICKS_PRISMARINE, false);
            this.fillWithBlocks(llllllllllllIIlIIIIlIIllIlllllIl, llllllllllllIIlIIIIlIIllIlllllII, 9, 0, 3, 11, 0, 9, Penthouse.BRICKS_PRISMARINE, Penthouse.BRICKS_PRISMARINE, false);
            this.fillWithBlocks(llllllllllllIIlIIIIlIIllIlllllIl, llllllllllllIIlIIIIlIIllIlllllII, 4, 0, 9, 9, 0, 11, Penthouse.BRICKS_PRISMARINE, Penthouse.BRICKS_PRISMARINE, false);
            this.setBlockState(llllllllllllIIlIIIIlIIllIlllllIl, Penthouse.BRICKS_PRISMARINE, 5, 0, 8, llllllllllllIIlIIIIlIIllIlllllII);
            this.setBlockState(llllllllllllIIlIIIIlIIllIlllllIl, Penthouse.BRICKS_PRISMARINE, 8, 0, 8, llllllllllllIIlIIIIlIIllIlllllII);
            this.setBlockState(llllllllllllIIlIIIIlIIllIlllllIl, Penthouse.BRICKS_PRISMARINE, 10, 0, 10, llllllllllllIIlIIIIlIIllIlllllII);
            this.setBlockState(llllllllllllIIlIIIIlIIllIlllllIl, Penthouse.BRICKS_PRISMARINE, 3, 0, 10, llllllllllllIIlIIIIlIIllIlllllII);
            this.fillWithBlocks(llllllllllllIIlIIIIlIIllIlllllIl, llllllllllllIIlIIIIlIIllIlllllII, 3, 0, 3, 3, 0, 7, Penthouse.DARK_PRISMARINE, Penthouse.DARK_PRISMARINE, false);
            this.fillWithBlocks(llllllllllllIIlIIIIlIIllIlllllIl, llllllllllllIIlIIIIlIIllIlllllII, 10, 0, 3, 10, 0, 7, Penthouse.DARK_PRISMARINE, Penthouse.DARK_PRISMARINE, false);
            this.fillWithBlocks(llllllllllllIIlIIIIlIIllIlllllIl, llllllllllllIIlIIIIlIIllIlllllII, 6, 0, 10, 7, 0, 10, Penthouse.DARK_PRISMARINE, Penthouse.DARK_PRISMARINE, false);
            int llllllllllllIIlIIIIlIIlllIIIIIIl = 3;
            for (int llllllllllllIIlIIIIlIIlllIIIIIII = 0; llllllllllllIIlIIIIlIIlllIIIIIII < 2; ++llllllllllllIIlIIIIlIIlllIIIIIII) {
                for (int llllllllllllIIlIIIIlIIllIlllllll = 2; llllllllllllIIlIIIIlIIllIlllllll <= 8; llllllllllllIIlIIIIlIIllIlllllll += 3) {
                    this.fillWithBlocks(llllllllllllIIlIIIIlIIllIlllllIl, llllllllllllIIlIIIIlIIllIlllllII, llllllllllllIIlIIIIlIIlllIIIIIIl, 0, llllllllllllIIlIIIIlIIllIlllllll, llllllllllllIIlIIIIlIIlllIIIIIIl, 2, llllllllllllIIlIIIIlIIllIlllllll, Penthouse.BRICKS_PRISMARINE, Penthouse.BRICKS_PRISMARINE, false);
                }
                llllllllllllIIlIIIIlIIlllIIIIIIl = 10;
            }
            this.fillWithBlocks(llllllllllllIIlIIIIlIIllIlllllIl, llllllllllllIIlIIIIlIIllIlllllII, 5, 0, 10, 5, 2, 10, Penthouse.BRICKS_PRISMARINE, Penthouse.BRICKS_PRISMARINE, false);
            this.fillWithBlocks(llllllllllllIIlIIIIlIIllIlllllIl, llllllllllllIIlIIIIlIIllIlllllII, 8, 0, 10, 8, 2, 10, Penthouse.BRICKS_PRISMARINE, Penthouse.BRICKS_PRISMARINE, false);
            this.fillWithBlocks(llllllllllllIIlIIIIlIIllIlllllIl, llllllllllllIIlIIIIlIIllIlllllII, 6, -1, 7, 7, -1, 8, Penthouse.DARK_PRISMARINE, Penthouse.DARK_PRISMARINE, false);
            this.generateWaterBox(llllllllllllIIlIIIIlIIllIlllllIl, llllllllllllIIlIIIIlIIllIlllllII, 6, -1, 3, 7, -1, 4, false);
            this.spawnElder(llllllllllllIIlIIIIlIIllIlllllIl, llllllllllllIIlIIIIlIIllIlllllII, 6, 1, 6);
            return true;
        }
        
        public Penthouse() {
        }
    }
    
    public static class EntryRoom extends Piece
    {
        @Override
        public boolean addComponentParts(final World lllllllllllllIIIIlIlIIlllllIllll, final Random lllllllllllllIIIIlIlIIllllllIIlI, final StructureBoundingBox lllllllllllllIIIIlIlIIllllllIIIl) {
            this.fillWithBlocks(lllllllllllllIIIIlIlIIlllllIllll, lllllllllllllIIIIlIlIIllllllIIIl, 0, 3, 0, 2, 3, 7, EntryRoom.BRICKS_PRISMARINE, EntryRoom.BRICKS_PRISMARINE, false);
            this.fillWithBlocks(lllllllllllllIIIIlIlIIlllllIllll, lllllllllllllIIIIlIlIIllllllIIIl, 5, 3, 0, 7, 3, 7, EntryRoom.BRICKS_PRISMARINE, EntryRoom.BRICKS_PRISMARINE, false);
            this.fillWithBlocks(lllllllllllllIIIIlIlIIlllllIllll, lllllllllllllIIIIlIlIIllllllIIIl, 0, 2, 0, 1, 2, 7, EntryRoom.BRICKS_PRISMARINE, EntryRoom.BRICKS_PRISMARINE, false);
            this.fillWithBlocks(lllllllllllllIIIIlIlIIlllllIllll, lllllllllllllIIIIlIlIIllllllIIIl, 6, 2, 0, 7, 2, 7, EntryRoom.BRICKS_PRISMARINE, EntryRoom.BRICKS_PRISMARINE, false);
            this.fillWithBlocks(lllllllllllllIIIIlIlIIlllllIllll, lllllllllllllIIIIlIlIIllllllIIIl, 0, 1, 0, 0, 1, 7, EntryRoom.BRICKS_PRISMARINE, EntryRoom.BRICKS_PRISMARINE, false);
            this.fillWithBlocks(lllllllllllllIIIIlIlIIlllllIllll, lllllllllllllIIIIlIlIIllllllIIIl, 7, 1, 0, 7, 1, 7, EntryRoom.BRICKS_PRISMARINE, EntryRoom.BRICKS_PRISMARINE, false);
            this.fillWithBlocks(lllllllllllllIIIIlIlIIlllllIllll, lllllllllllllIIIIlIlIIllllllIIIl, 0, 1, 7, 7, 3, 7, EntryRoom.BRICKS_PRISMARINE, EntryRoom.BRICKS_PRISMARINE, false);
            this.fillWithBlocks(lllllllllllllIIIIlIlIIlllllIllll, lllllllllllllIIIIlIlIIllllllIIIl, 1, 1, 0, 2, 3, 0, EntryRoom.BRICKS_PRISMARINE, EntryRoom.BRICKS_PRISMARINE, false);
            this.fillWithBlocks(lllllllllllllIIIIlIlIIlllllIllll, lllllllllllllIIIIlIlIIllllllIIIl, 5, 1, 0, 6, 3, 0, EntryRoom.BRICKS_PRISMARINE, EntryRoom.BRICKS_PRISMARINE, false);
            if (this.roomDefinition.hasOpening[EnumFacing.NORTH.getIndex()]) {
                this.generateWaterBox(lllllllllllllIIIIlIlIIlllllIllll, lllllllllllllIIIIlIlIIllllllIIIl, 3, 1, 7, 4, 2, 7, false);
            }
            if (this.roomDefinition.hasOpening[EnumFacing.WEST.getIndex()]) {
                this.generateWaterBox(lllllllllllllIIIIlIlIIlllllIllll, lllllllllllllIIIIlIlIIllllllIIIl, 0, 1, 3, 1, 2, 4, false);
            }
            if (this.roomDefinition.hasOpening[EnumFacing.EAST.getIndex()]) {
                this.generateWaterBox(lllllllllllllIIIIlIlIIlllllIllll, lllllllllllllIIIIlIlIIllllllIIIl, 6, 1, 3, 7, 2, 4, false);
            }
            return true;
        }
        
        public EntryRoom() {
        }
        
        public EntryRoom(final EnumFacing lllllllllllllIIIIlIlIIlllllllIIl, final RoomDefinition lllllllllllllIIIIlIlIIlllllllIll) {
            super(1, lllllllllllllIIIIlIlIIlllllllIIl, lllllllllllllIIIIlIlIIlllllllIll, 1, 1, 1);
        }
    }
    
    public static class WingRoom extends Piece
    {
        private /* synthetic */ int mainDesign;
        
        public WingRoom() {
        }
        
        public WingRoom(final EnumFacing lllllllllllIIlllIllllIIIIIlIlIII, final StructureBoundingBox lllllllllllIIlllIllllIIIIIlIlIll, final int lllllllllllIIlllIllllIIIIIlIlIlI) {
            super(lllllllllllIIlllIllllIIIIIlIlIII, lllllllllllIIlllIllllIIIIIlIlIll);
            this.mainDesign = (lllllllllllIIlllIllllIIIIIlIlIlI & 0x1);
        }
        
        @Override
        public boolean addComponentParts(final World lllllllllllIIlllIllllIIIIIIlllIl, final Random lllllllllllIIlllIllllIIIIIIlllII, final StructureBoundingBox lllllllllllIIlllIllllIIIIIIllIll) {
            if (this.mainDesign == 0) {
                for (int lllllllllllIIlllIllllIIIIIIllIlI = 0; lllllllllllIIlllIllllIIIIIIllIlI < 4; ++lllllllllllIIlllIllllIIIIIIllIlI) {
                    this.fillWithBlocks(lllllllllllIIlllIllllIIIIIIlllIl, lllllllllllIIlllIllllIIIIIIllIll, 10 - lllllllllllIIlllIllllIIIIIIllIlI, 3 - lllllllllllIIlllIllllIIIIIIllIlI, 20 - lllllllllllIIlllIllllIIIIIIllIlI, 12 + lllllllllllIIlllIllllIIIIIIllIlI, 3 - lllllllllllIIlllIllllIIIIIIllIlI, 20, WingRoom.BRICKS_PRISMARINE, WingRoom.BRICKS_PRISMARINE, false);
                }
                this.fillWithBlocks(lllllllllllIIlllIllllIIIIIIlllIl, lllllllllllIIlllIllllIIIIIIllIll, 7, 0, 6, 15, 0, 16, WingRoom.BRICKS_PRISMARINE, WingRoom.BRICKS_PRISMARINE, false);
                this.fillWithBlocks(lllllllllllIIlllIllllIIIIIIlllIl, lllllllllllIIlllIllllIIIIIIllIll, 6, 0, 6, 6, 3, 20, WingRoom.BRICKS_PRISMARINE, WingRoom.BRICKS_PRISMARINE, false);
                this.fillWithBlocks(lllllllllllIIlllIllllIIIIIIlllIl, lllllllllllIIlllIllllIIIIIIllIll, 16, 0, 6, 16, 3, 20, WingRoom.BRICKS_PRISMARINE, WingRoom.BRICKS_PRISMARINE, false);
                this.fillWithBlocks(lllllllllllIIlllIllllIIIIIIlllIl, lllllllllllIIlllIllllIIIIIIllIll, 7, 1, 7, 7, 1, 20, WingRoom.BRICKS_PRISMARINE, WingRoom.BRICKS_PRISMARINE, false);
                this.fillWithBlocks(lllllllllllIIlllIllllIIIIIIlllIl, lllllllllllIIlllIllllIIIIIIllIll, 15, 1, 7, 15, 1, 20, WingRoom.BRICKS_PRISMARINE, WingRoom.BRICKS_PRISMARINE, false);
                this.fillWithBlocks(lllllllllllIIlllIllllIIIIIIlllIl, lllllllllllIIlllIllllIIIIIIllIll, 7, 1, 6, 9, 3, 6, WingRoom.BRICKS_PRISMARINE, WingRoom.BRICKS_PRISMARINE, false);
                this.fillWithBlocks(lllllllllllIIlllIllllIIIIIIlllIl, lllllllllllIIlllIllllIIIIIIllIll, 13, 1, 6, 15, 3, 6, WingRoom.BRICKS_PRISMARINE, WingRoom.BRICKS_PRISMARINE, false);
                this.fillWithBlocks(lllllllllllIIlllIllllIIIIIIlllIl, lllllllllllIIlllIllllIIIIIIllIll, 8, 1, 7, 9, 1, 7, WingRoom.BRICKS_PRISMARINE, WingRoom.BRICKS_PRISMARINE, false);
                this.fillWithBlocks(lllllllllllIIlllIllllIIIIIIlllIl, lllllllllllIIlllIllllIIIIIIllIll, 13, 1, 7, 14, 1, 7, WingRoom.BRICKS_PRISMARINE, WingRoom.BRICKS_PRISMARINE, false);
                this.fillWithBlocks(lllllllllllIIlllIllllIIIIIIlllIl, lllllllllllIIlllIllllIIIIIIllIll, 9, 0, 5, 13, 0, 5, WingRoom.BRICKS_PRISMARINE, WingRoom.BRICKS_PRISMARINE, false);
                this.fillWithBlocks(lllllllllllIIlllIllllIIIIIIlllIl, lllllllllllIIlllIllllIIIIIIllIll, 10, 0, 7, 12, 0, 7, WingRoom.DARK_PRISMARINE, WingRoom.DARK_PRISMARINE, false);
                this.fillWithBlocks(lllllllllllIIlllIllllIIIIIIlllIl, lllllllllllIIlllIllllIIIIIIllIll, 8, 0, 10, 8, 0, 12, WingRoom.DARK_PRISMARINE, WingRoom.DARK_PRISMARINE, false);
                this.fillWithBlocks(lllllllllllIIlllIllllIIIIIIlllIl, lllllllllllIIlllIllllIIIIIIllIll, 14, 0, 10, 14, 0, 12, WingRoom.DARK_PRISMARINE, WingRoom.DARK_PRISMARINE, false);
                for (int lllllllllllIIlllIllllIIIIIIllIIl = 18; lllllllllllIIlllIllllIIIIIIllIIl >= 7; lllllllllllIIlllIllllIIIIIIllIIl -= 3) {
                    this.setBlockState(lllllllllllIIlllIllllIIIIIIlllIl, WingRoom.SEA_LANTERN, 6, 3, lllllllllllIIlllIllllIIIIIIllIIl, lllllllllllIIlllIllllIIIIIIllIll);
                    this.setBlockState(lllllllllllIIlllIllllIIIIIIlllIl, WingRoom.SEA_LANTERN, 16, 3, lllllllllllIIlllIllllIIIIIIllIIl, lllllllllllIIlllIllllIIIIIIllIll);
                }
                this.setBlockState(lllllllllllIIlllIllllIIIIIIlllIl, WingRoom.SEA_LANTERN, 10, 0, 10, lllllllllllIIlllIllllIIIIIIllIll);
                this.setBlockState(lllllllllllIIlllIllllIIIIIIlllIl, WingRoom.SEA_LANTERN, 12, 0, 10, lllllllllllIIlllIllllIIIIIIllIll);
                this.setBlockState(lllllllllllIIlllIllllIIIIIIlllIl, WingRoom.SEA_LANTERN, 10, 0, 12, lllllllllllIIlllIllllIIIIIIllIll);
                this.setBlockState(lllllllllllIIlllIllllIIIIIIlllIl, WingRoom.SEA_LANTERN, 12, 0, 12, lllllllllllIIlllIllllIIIIIIllIll);
                this.setBlockState(lllllllllllIIlllIllllIIIIIIlllIl, WingRoom.SEA_LANTERN, 8, 3, 6, lllllllllllIIlllIllllIIIIIIllIll);
                this.setBlockState(lllllllllllIIlllIllllIIIIIIlllIl, WingRoom.SEA_LANTERN, 14, 3, 6, lllllllllllIIlllIllllIIIIIIllIll);
                this.setBlockState(lllllllllllIIlllIllllIIIIIIlllIl, WingRoom.BRICKS_PRISMARINE, 4, 2, 4, lllllllllllIIlllIllllIIIIIIllIll);
                this.setBlockState(lllllllllllIIlllIllllIIIIIIlllIl, WingRoom.SEA_LANTERN, 4, 1, 4, lllllllllllIIlllIllllIIIIIIllIll);
                this.setBlockState(lllllllllllIIlllIllllIIIIIIlllIl, WingRoom.BRICKS_PRISMARINE, 4, 0, 4, lllllllllllIIlllIllllIIIIIIllIll);
                this.setBlockState(lllllllllllIIlllIllllIIIIIIlllIl, WingRoom.BRICKS_PRISMARINE, 18, 2, 4, lllllllllllIIlllIllllIIIIIIllIll);
                this.setBlockState(lllllllllllIIlllIllllIIIIIIlllIl, WingRoom.SEA_LANTERN, 18, 1, 4, lllllllllllIIlllIllllIIIIIIllIll);
                this.setBlockState(lllllllllllIIlllIllllIIIIIIlllIl, WingRoom.BRICKS_PRISMARINE, 18, 0, 4, lllllllllllIIlllIllllIIIIIIllIll);
                this.setBlockState(lllllllllllIIlllIllllIIIIIIlllIl, WingRoom.BRICKS_PRISMARINE, 4, 2, 18, lllllllllllIIlllIllllIIIIIIllIll);
                this.setBlockState(lllllllllllIIlllIllllIIIIIIlllIl, WingRoom.SEA_LANTERN, 4, 1, 18, lllllllllllIIlllIllllIIIIIIllIll);
                this.setBlockState(lllllllllllIIlllIllllIIIIIIlllIl, WingRoom.BRICKS_PRISMARINE, 4, 0, 18, lllllllllllIIlllIllllIIIIIIllIll);
                this.setBlockState(lllllllllllIIlllIllllIIIIIIlllIl, WingRoom.BRICKS_PRISMARINE, 18, 2, 18, lllllllllllIIlllIllllIIIIIIllIll);
                this.setBlockState(lllllllllllIIlllIllllIIIIIIlllIl, WingRoom.SEA_LANTERN, 18, 1, 18, lllllllllllIIlllIllllIIIIIIllIll);
                this.setBlockState(lllllllllllIIlllIllllIIIIIIlllIl, WingRoom.BRICKS_PRISMARINE, 18, 0, 18, lllllllllllIIlllIllllIIIIIIllIll);
                this.setBlockState(lllllllllllIIlllIllllIIIIIIlllIl, WingRoom.BRICKS_PRISMARINE, 9, 7, 20, lllllllllllIIlllIllllIIIIIIllIll);
                this.setBlockState(lllllllllllIIlllIllllIIIIIIlllIl, WingRoom.BRICKS_PRISMARINE, 13, 7, 20, lllllllllllIIlllIllllIIIIIIllIll);
                this.fillWithBlocks(lllllllllllIIlllIllllIIIIIIlllIl, lllllllllllIIlllIllllIIIIIIllIll, 6, 0, 21, 7, 4, 21, WingRoom.BRICKS_PRISMARINE, WingRoom.BRICKS_PRISMARINE, false);
                this.fillWithBlocks(lllllllllllIIlllIllllIIIIIIlllIl, lllllllllllIIlllIllllIIIIIIllIll, 15, 0, 21, 16, 4, 21, WingRoom.BRICKS_PRISMARINE, WingRoom.BRICKS_PRISMARINE, false);
                this.spawnElder(lllllllllllIIlllIllllIIIIIIlllIl, lllllllllllIIlllIllllIIIIIIllIll, 11, 2, 16);
            }
            else if (this.mainDesign == 1) {
                this.fillWithBlocks(lllllllllllIIlllIllllIIIIIIlllIl, lllllllllllIIlllIllllIIIIIIllIll, 9, 3, 18, 13, 3, 20, WingRoom.BRICKS_PRISMARINE, WingRoom.BRICKS_PRISMARINE, false);
                this.fillWithBlocks(lllllllllllIIlllIllllIIIIIIlllIl, lllllllllllIIlllIllllIIIIIIllIll, 9, 0, 18, 9, 2, 18, WingRoom.BRICKS_PRISMARINE, WingRoom.BRICKS_PRISMARINE, false);
                this.fillWithBlocks(lllllllllllIIlllIllllIIIIIIlllIl, lllllllllllIIlllIllllIIIIIIllIll, 13, 0, 18, 13, 2, 18, WingRoom.BRICKS_PRISMARINE, WingRoom.BRICKS_PRISMARINE, false);
                int lllllllllllIIlllIllllIIIIIIllIII = 9;
                final int lllllllllllIIlllIllllIIIIIIlIlll = 20;
                final int lllllllllllIIlllIllllIIIIIIlIllI = 5;
                for (int lllllllllllIIlllIllllIIIIIIlIlIl = 0; lllllllllllIIlllIllllIIIIIIlIlIl < 2; ++lllllllllllIIlllIllllIIIIIIlIlIl) {
                    this.setBlockState(lllllllllllIIlllIllllIIIIIIlllIl, WingRoom.BRICKS_PRISMARINE, lllllllllllIIlllIllllIIIIIIllIII, 6, 20, lllllllllllIIlllIllllIIIIIIllIll);
                    this.setBlockState(lllllllllllIIlllIllllIIIIIIlllIl, WingRoom.SEA_LANTERN, lllllllllllIIlllIllllIIIIIIllIII, 5, 20, lllllllllllIIlllIllllIIIIIIllIll);
                    this.setBlockState(lllllllllllIIlllIllllIIIIIIlllIl, WingRoom.BRICKS_PRISMARINE, lllllllllllIIlllIllllIIIIIIllIII, 4, 20, lllllllllllIIlllIllllIIIIIIllIll);
                    lllllllllllIIlllIllllIIIIIIllIII = 13;
                }
                this.fillWithBlocks(lllllllllllIIlllIllllIIIIIIlllIl, lllllllllllIIlllIllllIIIIIIllIll, 7, 3, 7, 15, 3, 14, WingRoom.BRICKS_PRISMARINE, WingRoom.BRICKS_PRISMARINE, false);
                lllllllllllIIlllIllllIIIIIIllIII = 10;
                for (int lllllllllllIIlllIllllIIIIIIlIlII = 0; lllllllllllIIlllIllllIIIIIIlIlII < 2; ++lllllllllllIIlllIllllIIIIIIlIlII) {
                    this.fillWithBlocks(lllllllllllIIlllIllllIIIIIIlllIl, lllllllllllIIlllIllllIIIIIIllIll, lllllllllllIIlllIllllIIIIIIllIII, 0, 10, lllllllllllIIlllIllllIIIIIIllIII, 6, 10, WingRoom.BRICKS_PRISMARINE, WingRoom.BRICKS_PRISMARINE, false);
                    this.fillWithBlocks(lllllllllllIIlllIllllIIIIIIlllIl, lllllllllllIIlllIllllIIIIIIllIll, lllllllllllIIlllIllllIIIIIIllIII, 0, 12, lllllllllllIIlllIllllIIIIIIllIII, 6, 12, WingRoom.BRICKS_PRISMARINE, WingRoom.BRICKS_PRISMARINE, false);
                    this.setBlockState(lllllllllllIIlllIllllIIIIIIlllIl, WingRoom.SEA_LANTERN, lllllllllllIIlllIllllIIIIIIllIII, 0, 10, lllllllllllIIlllIllllIIIIIIllIll);
                    this.setBlockState(lllllllllllIIlllIllllIIIIIIlllIl, WingRoom.SEA_LANTERN, lllllllllllIIlllIllllIIIIIIllIII, 0, 12, lllllllllllIIlllIllllIIIIIIllIll);
                    this.setBlockState(lllllllllllIIlllIllllIIIIIIlllIl, WingRoom.SEA_LANTERN, lllllllllllIIlllIllllIIIIIIllIII, 4, 10, lllllllllllIIlllIllllIIIIIIllIll);
                    this.setBlockState(lllllllllllIIlllIllllIIIIIIlllIl, WingRoom.SEA_LANTERN, lllllllllllIIlllIllllIIIIIIllIII, 4, 12, lllllllllllIIlllIllllIIIIIIllIll);
                    lllllllllllIIlllIllllIIIIIIllIII = 12;
                }
                lllllllllllIIlllIllllIIIIIIllIII = 8;
                for (int lllllllllllIIlllIllllIIIIIIlIIll = 0; lllllllllllIIlllIllllIIIIIIlIIll < 2; ++lllllllllllIIlllIllllIIIIIIlIIll) {
                    this.fillWithBlocks(lllllllllllIIlllIllllIIIIIIlllIl, lllllllllllIIlllIllllIIIIIIllIll, lllllllllllIIlllIllllIIIIIIllIII, 0, 7, lllllllllllIIlllIllllIIIIIIllIII, 2, 7, WingRoom.BRICKS_PRISMARINE, WingRoom.BRICKS_PRISMARINE, false);
                    this.fillWithBlocks(lllllllllllIIlllIllllIIIIIIlllIl, lllllllllllIIlllIllllIIIIIIllIll, lllllllllllIIlllIllllIIIIIIllIII, 0, 14, lllllllllllIIlllIllllIIIIIIllIII, 2, 14, WingRoom.BRICKS_PRISMARINE, WingRoom.BRICKS_PRISMARINE, false);
                    lllllllllllIIlllIllllIIIIIIllIII = 14;
                }
                this.fillWithBlocks(lllllllllllIIlllIllllIIIIIIlllIl, lllllllllllIIlllIllllIIIIIIllIll, 8, 3, 8, 8, 3, 13, WingRoom.DARK_PRISMARINE, WingRoom.DARK_PRISMARINE, false);
                this.fillWithBlocks(lllllllllllIIlllIllllIIIIIIlllIl, lllllllllllIIlllIllllIIIIIIllIll, 14, 3, 8, 14, 3, 13, WingRoom.DARK_PRISMARINE, WingRoom.DARK_PRISMARINE, false);
                this.spawnElder(lllllllllllIIlllIllllIIIIIIlllIl, lllllllllllIIlllIllllIIIIIIllIll, 11, 5, 13);
            }
            return true;
        }
    }
    
    public static class DoubleYRoom extends Piece
    {
        @Override
        public boolean addComponentParts(final World llllllllllllIIIlIllIIIIIIlIIIIIl, final Random llllllllllllIIIlIllIIIIIIlIIIIII, final StructureBoundingBox llllllllllllIIIlIllIIIIIIIllIlll) {
            if (this.roomDefinition.index / 25 > 0) {
                this.generateDefaultFloor(llllllllllllIIIlIllIIIIIIlIIIIIl, llllllllllllIIIlIllIIIIIIIllIlll, 0, 0, this.roomDefinition.hasOpening[EnumFacing.DOWN.getIndex()]);
            }
            final RoomDefinition llllllllllllIIIlIllIIIIIIIlllllI = this.roomDefinition.connections[EnumFacing.UP.getIndex()];
            if (llllllllllllIIIlIllIIIIIIIlllllI.connections[EnumFacing.UP.getIndex()] == null) {
                this.generateBoxOnFillOnly(llllllllllllIIIlIllIIIIIIlIIIIIl, llllllllllllIIIlIllIIIIIIIllIlll, 1, 8, 1, 6, 8, 6, DoubleYRoom.ROUGH_PRISMARINE);
            }
            this.fillWithBlocks(llllllllllllIIIlIllIIIIIIlIIIIIl, llllllllllllIIIlIllIIIIIIIllIlll, 0, 4, 0, 0, 4, 7, DoubleYRoom.BRICKS_PRISMARINE, DoubleYRoom.BRICKS_PRISMARINE, false);
            this.fillWithBlocks(llllllllllllIIIlIllIIIIIIlIIIIIl, llllllllllllIIIlIllIIIIIIIllIlll, 7, 4, 0, 7, 4, 7, DoubleYRoom.BRICKS_PRISMARINE, DoubleYRoom.BRICKS_PRISMARINE, false);
            this.fillWithBlocks(llllllllllllIIIlIllIIIIIIlIIIIIl, llllllllllllIIIlIllIIIIIIIllIlll, 1, 4, 0, 6, 4, 0, DoubleYRoom.BRICKS_PRISMARINE, DoubleYRoom.BRICKS_PRISMARINE, false);
            this.fillWithBlocks(llllllllllllIIIlIllIIIIIIlIIIIIl, llllllllllllIIIlIllIIIIIIIllIlll, 1, 4, 7, 6, 4, 7, DoubleYRoom.BRICKS_PRISMARINE, DoubleYRoom.BRICKS_PRISMARINE, false);
            this.fillWithBlocks(llllllllllllIIIlIllIIIIIIlIIIIIl, llllllllllllIIIlIllIIIIIIIllIlll, 2, 4, 1, 2, 4, 2, DoubleYRoom.BRICKS_PRISMARINE, DoubleYRoom.BRICKS_PRISMARINE, false);
            this.fillWithBlocks(llllllllllllIIIlIllIIIIIIlIIIIIl, llllllllllllIIIlIllIIIIIIIllIlll, 1, 4, 2, 1, 4, 2, DoubleYRoom.BRICKS_PRISMARINE, DoubleYRoom.BRICKS_PRISMARINE, false);
            this.fillWithBlocks(llllllllllllIIIlIllIIIIIIlIIIIIl, llllllllllllIIIlIllIIIIIIIllIlll, 5, 4, 1, 5, 4, 2, DoubleYRoom.BRICKS_PRISMARINE, DoubleYRoom.BRICKS_PRISMARINE, false);
            this.fillWithBlocks(llllllllllllIIIlIllIIIIIIlIIIIIl, llllllllllllIIIlIllIIIIIIIllIlll, 6, 4, 2, 6, 4, 2, DoubleYRoom.BRICKS_PRISMARINE, DoubleYRoom.BRICKS_PRISMARINE, false);
            this.fillWithBlocks(llllllllllllIIIlIllIIIIIIlIIIIIl, llllllllllllIIIlIllIIIIIIIllIlll, 2, 4, 5, 2, 4, 6, DoubleYRoom.BRICKS_PRISMARINE, DoubleYRoom.BRICKS_PRISMARINE, false);
            this.fillWithBlocks(llllllllllllIIIlIllIIIIIIlIIIIIl, llllllllllllIIIlIllIIIIIIIllIlll, 1, 4, 5, 1, 4, 5, DoubleYRoom.BRICKS_PRISMARINE, DoubleYRoom.BRICKS_PRISMARINE, false);
            this.fillWithBlocks(llllllllllllIIIlIllIIIIIIlIIIIIl, llllllllllllIIIlIllIIIIIIIllIlll, 5, 4, 5, 5, 4, 6, DoubleYRoom.BRICKS_PRISMARINE, DoubleYRoom.BRICKS_PRISMARINE, false);
            this.fillWithBlocks(llllllllllllIIIlIllIIIIIIlIIIIIl, llllllllllllIIIlIllIIIIIIIllIlll, 6, 4, 5, 6, 4, 5, DoubleYRoom.BRICKS_PRISMARINE, DoubleYRoom.BRICKS_PRISMARINE, false);
            RoomDefinition llllllllllllIIIlIllIIIIIIIllllIl = this.roomDefinition;
            for (int llllllllllllIIIlIllIIIIIIIllllII = 1; llllllllllllIIIlIllIIIIIIIllllII <= 5; llllllllllllIIIlIllIIIIIIIllllII += 4) {
                int llllllllllllIIIlIllIIIIIIIlllIll = 0;
                if (llllllllllllIIIlIllIIIIIIIllllIl.hasOpening[EnumFacing.SOUTH.getIndex()]) {
                    this.fillWithBlocks(llllllllllllIIIlIllIIIIIIlIIIIIl, llllllllllllIIIlIllIIIIIIIllIlll, 2, llllllllllllIIIlIllIIIIIIIllllII, llllllllllllIIIlIllIIIIIIIlllIll, 2, llllllllllllIIIlIllIIIIIIIllllII + 2, llllllllllllIIIlIllIIIIIIIlllIll, DoubleYRoom.BRICKS_PRISMARINE, DoubleYRoom.BRICKS_PRISMARINE, false);
                    this.fillWithBlocks(llllllllllllIIIlIllIIIIIIlIIIIIl, llllllllllllIIIlIllIIIIIIIllIlll, 5, llllllllllllIIIlIllIIIIIIIllllII, llllllllllllIIIlIllIIIIIIIlllIll, 5, llllllllllllIIIlIllIIIIIIIllllII + 2, llllllllllllIIIlIllIIIIIIIlllIll, DoubleYRoom.BRICKS_PRISMARINE, DoubleYRoom.BRICKS_PRISMARINE, false);
                    this.fillWithBlocks(llllllllllllIIIlIllIIIIIIlIIIIIl, llllllllllllIIIlIllIIIIIIIllIlll, 3, llllllllllllIIIlIllIIIIIIIllllII + 2, llllllllllllIIIlIllIIIIIIIlllIll, 4, llllllllllllIIIlIllIIIIIIIllllII + 2, llllllllllllIIIlIllIIIIIIIlllIll, DoubleYRoom.BRICKS_PRISMARINE, DoubleYRoom.BRICKS_PRISMARINE, false);
                }
                else {
                    this.fillWithBlocks(llllllllllllIIIlIllIIIIIIlIIIIIl, llllllllllllIIIlIllIIIIIIIllIlll, 0, llllllllllllIIIlIllIIIIIIIllllII, llllllllllllIIIlIllIIIIIIIlllIll, 7, llllllllllllIIIlIllIIIIIIIllllII + 2, llllllllllllIIIlIllIIIIIIIlllIll, DoubleYRoom.BRICKS_PRISMARINE, DoubleYRoom.BRICKS_PRISMARINE, false);
                    this.fillWithBlocks(llllllllllllIIIlIllIIIIIIlIIIIIl, llllllllllllIIIlIllIIIIIIIllIlll, 0, llllllllllllIIIlIllIIIIIIIllllII + 1, llllllllllllIIIlIllIIIIIIIlllIll, 7, llllllllllllIIIlIllIIIIIIIllllII + 1, llllllllllllIIIlIllIIIIIIIlllIll, DoubleYRoom.ROUGH_PRISMARINE, DoubleYRoom.ROUGH_PRISMARINE, false);
                }
                llllllllllllIIIlIllIIIIIIIlllIll = 7;
                if (llllllllllllIIIlIllIIIIIIIllllIl.hasOpening[EnumFacing.NORTH.getIndex()]) {
                    this.fillWithBlocks(llllllllllllIIIlIllIIIIIIlIIIIIl, llllllllllllIIIlIllIIIIIIIllIlll, 2, llllllllllllIIIlIllIIIIIIIllllII, llllllllllllIIIlIllIIIIIIIlllIll, 2, llllllllllllIIIlIllIIIIIIIllllII + 2, llllllllllllIIIlIllIIIIIIIlllIll, DoubleYRoom.BRICKS_PRISMARINE, DoubleYRoom.BRICKS_PRISMARINE, false);
                    this.fillWithBlocks(llllllllllllIIIlIllIIIIIIlIIIIIl, llllllllllllIIIlIllIIIIIIIllIlll, 5, llllllllllllIIIlIllIIIIIIIllllII, llllllllllllIIIlIllIIIIIIIlllIll, 5, llllllllllllIIIlIllIIIIIIIllllII + 2, llllllllllllIIIlIllIIIIIIIlllIll, DoubleYRoom.BRICKS_PRISMARINE, DoubleYRoom.BRICKS_PRISMARINE, false);
                    this.fillWithBlocks(llllllllllllIIIlIllIIIIIIlIIIIIl, llllllllllllIIIlIllIIIIIIIllIlll, 3, llllllllllllIIIlIllIIIIIIIllllII + 2, llllllllllllIIIlIllIIIIIIIlllIll, 4, llllllllllllIIIlIllIIIIIIIllllII + 2, llllllllllllIIIlIllIIIIIIIlllIll, DoubleYRoom.BRICKS_PRISMARINE, DoubleYRoom.BRICKS_PRISMARINE, false);
                }
                else {
                    this.fillWithBlocks(llllllllllllIIIlIllIIIIIIlIIIIIl, llllllllllllIIIlIllIIIIIIIllIlll, 0, llllllllllllIIIlIllIIIIIIIllllII, llllllllllllIIIlIllIIIIIIIlllIll, 7, llllllllllllIIIlIllIIIIIIIllllII + 2, llllllllllllIIIlIllIIIIIIIlllIll, DoubleYRoom.BRICKS_PRISMARINE, DoubleYRoom.BRICKS_PRISMARINE, false);
                    this.fillWithBlocks(llllllllllllIIIlIllIIIIIIlIIIIIl, llllllllllllIIIlIllIIIIIIIllIlll, 0, llllllllllllIIIlIllIIIIIIIllllII + 1, llllllllllllIIIlIllIIIIIIIlllIll, 7, llllllllllllIIIlIllIIIIIIIllllII + 1, llllllllllllIIIlIllIIIIIIIlllIll, DoubleYRoom.ROUGH_PRISMARINE, DoubleYRoom.ROUGH_PRISMARINE, false);
                }
                int llllllllllllIIIlIllIIIIIIIlllIlI = 0;
                if (llllllllllllIIIlIllIIIIIIIllllIl.hasOpening[EnumFacing.WEST.getIndex()]) {
                    this.fillWithBlocks(llllllllllllIIIlIllIIIIIIlIIIIIl, llllllllllllIIIlIllIIIIIIIllIlll, llllllllllllIIIlIllIIIIIIIlllIlI, llllllllllllIIIlIllIIIIIIIllllII, 2, llllllllllllIIIlIllIIIIIIIlllIlI, llllllllllllIIIlIllIIIIIIIllllII + 2, 2, DoubleYRoom.BRICKS_PRISMARINE, DoubleYRoom.BRICKS_PRISMARINE, false);
                    this.fillWithBlocks(llllllllllllIIIlIllIIIIIIlIIIIIl, llllllllllllIIIlIllIIIIIIIllIlll, llllllllllllIIIlIllIIIIIIIlllIlI, llllllllllllIIIlIllIIIIIIIllllII, 5, llllllllllllIIIlIllIIIIIIIlllIlI, llllllllllllIIIlIllIIIIIIIllllII + 2, 5, DoubleYRoom.BRICKS_PRISMARINE, DoubleYRoom.BRICKS_PRISMARINE, false);
                    this.fillWithBlocks(llllllllllllIIIlIllIIIIIIlIIIIIl, llllllllllllIIIlIllIIIIIIIllIlll, llllllllllllIIIlIllIIIIIIIlllIlI, llllllllllllIIIlIllIIIIIIIllllII + 2, 3, llllllllllllIIIlIllIIIIIIIlllIlI, llllllllllllIIIlIllIIIIIIIllllII + 2, 4, DoubleYRoom.BRICKS_PRISMARINE, DoubleYRoom.BRICKS_PRISMARINE, false);
                }
                else {
                    this.fillWithBlocks(llllllllllllIIIlIllIIIIIIlIIIIIl, llllllllllllIIIlIllIIIIIIIllIlll, llllllllllllIIIlIllIIIIIIIlllIlI, llllllllllllIIIlIllIIIIIIIllllII, 0, llllllllllllIIIlIllIIIIIIIlllIlI, llllllllllllIIIlIllIIIIIIIllllII + 2, 7, DoubleYRoom.BRICKS_PRISMARINE, DoubleYRoom.BRICKS_PRISMARINE, false);
                    this.fillWithBlocks(llllllllllllIIIlIllIIIIIIlIIIIIl, llllllllllllIIIlIllIIIIIIIllIlll, llllllllllllIIIlIllIIIIIIIlllIlI, llllllllllllIIIlIllIIIIIIIllllII + 1, 0, llllllllllllIIIlIllIIIIIIIlllIlI, llllllllllllIIIlIllIIIIIIIllllII + 1, 7, DoubleYRoom.ROUGH_PRISMARINE, DoubleYRoom.ROUGH_PRISMARINE, false);
                }
                llllllllllllIIIlIllIIIIIIIlllIlI = 7;
                if (llllllllllllIIIlIllIIIIIIIllllIl.hasOpening[EnumFacing.EAST.getIndex()]) {
                    this.fillWithBlocks(llllllllllllIIIlIllIIIIIIlIIIIIl, llllllllllllIIIlIllIIIIIIIllIlll, llllllllllllIIIlIllIIIIIIIlllIlI, llllllllllllIIIlIllIIIIIIIllllII, 2, llllllllllllIIIlIllIIIIIIIlllIlI, llllllllllllIIIlIllIIIIIIIllllII + 2, 2, DoubleYRoom.BRICKS_PRISMARINE, DoubleYRoom.BRICKS_PRISMARINE, false);
                    this.fillWithBlocks(llllllllllllIIIlIllIIIIIIlIIIIIl, llllllllllllIIIlIllIIIIIIIllIlll, llllllllllllIIIlIllIIIIIIIlllIlI, llllllllllllIIIlIllIIIIIIIllllII, 5, llllllllllllIIIlIllIIIIIIIlllIlI, llllllllllllIIIlIllIIIIIIIllllII + 2, 5, DoubleYRoom.BRICKS_PRISMARINE, DoubleYRoom.BRICKS_PRISMARINE, false);
                    this.fillWithBlocks(llllllllllllIIIlIllIIIIIIlIIIIIl, llllllllllllIIIlIllIIIIIIIllIlll, llllllllllllIIIlIllIIIIIIIlllIlI, llllllllllllIIIlIllIIIIIIIllllII + 2, 3, llllllllllllIIIlIllIIIIIIIlllIlI, llllllllllllIIIlIllIIIIIIIllllII + 2, 4, DoubleYRoom.BRICKS_PRISMARINE, DoubleYRoom.BRICKS_PRISMARINE, false);
                }
                else {
                    this.fillWithBlocks(llllllllllllIIIlIllIIIIIIlIIIIIl, llllllllllllIIIlIllIIIIIIIllIlll, llllllllllllIIIlIllIIIIIIIlllIlI, llllllllllllIIIlIllIIIIIIIllllII, 0, llllllllllllIIIlIllIIIIIIIlllIlI, llllllllllllIIIlIllIIIIIIIllllII + 2, 7, DoubleYRoom.BRICKS_PRISMARINE, DoubleYRoom.BRICKS_PRISMARINE, false);
                    this.fillWithBlocks(llllllllllllIIIlIllIIIIIIlIIIIIl, llllllllllllIIIlIllIIIIIIIllIlll, llllllllllllIIIlIllIIIIIIIlllIlI, llllllllllllIIIlIllIIIIIIIllllII + 1, 0, llllllllllllIIIlIllIIIIIIIlllIlI, llllllllllllIIIlIllIIIIIIIllllII + 1, 7, DoubleYRoom.ROUGH_PRISMARINE, DoubleYRoom.ROUGH_PRISMARINE, false);
                }
                llllllllllllIIIlIllIIIIIIIllllIl = llllllllllllIIIlIllIIIIIIIlllllI;
            }
            return true;
        }
        
        public DoubleYRoom() {
        }
        
        public DoubleYRoom(final EnumFacing llllllllllllIIIlIllIIIIIIlIlIIII, final RoomDefinition llllllllllllIIIlIllIIIIIIlIIllll, final Random llllllllllllIIIlIllIIIIIIlIIlllI) {
            super(1, llllllllllllIIIlIllIIIIIIlIlIIII, llllllllllllIIIlIllIIIIIIlIIllll, 1, 2, 1);
        }
    }
    
    static class XDoubleRoomFitHelper implements MonumentRoomFitHelper
    {
        @Override
        public Piece create(final EnumFacing lllllllllllIIIIIllIlIllIlIIlIlIl, final RoomDefinition lllllllllllIIIIIllIlIllIlIIlIlll, final Random lllllllllllIIIIIllIlIllIlIIlIIll) {
            lllllllllllIIIIIllIlIllIlIIlIlll.claimed = true;
            lllllllllllIIIIIllIlIllIlIIlIlll.connections[EnumFacing.EAST.getIndex()].claimed = true;
            return new DoubleXRoom(lllllllllllIIIIIllIlIllIlIIlIlIl, lllllllllllIIIIIllIlIllIlIIlIlll, lllllllllllIIIIIllIlIllIlIIlIIll);
        }
        
        @Override
        public boolean fits(final RoomDefinition lllllllllllIIIIIllIlIllIlIIlllIl) {
            return lllllllllllIIIIIllIlIllIlIIlllIl.hasOpening[EnumFacing.EAST.getIndex()] && !lllllllllllIIIIIllIlIllIlIIlllIl.connections[EnumFacing.EAST.getIndex()].claimed;
        }
        
        private XDoubleRoomFitHelper() {
        }
    }
    
    public static class DoubleXRoom extends Piece
    {
        public DoubleXRoom() {
        }
        
        @Override
        public boolean addComponentParts(final World llllllllllllIllIIIlIIlIlIIlIIlll, final Random llllllllllllIllIIIlIIlIlIIlIIllI, final StructureBoundingBox llllllllllllIllIIIlIIlIlIIlIIIII) {
            final RoomDefinition llllllllllllIllIIIlIIlIlIIlIIlII = this.roomDefinition.connections[EnumFacing.EAST.getIndex()];
            final RoomDefinition llllllllllllIllIIIlIIlIlIIlIIIll = this.roomDefinition;
            if (this.roomDefinition.index / 25 > 0) {
                this.generateDefaultFloor(llllllllllllIllIIIlIIlIlIIlIIlll, llllllllllllIllIIIlIIlIlIIlIIIII, 8, 0, llllllllllllIllIIIlIIlIlIIlIIlII.hasOpening[EnumFacing.DOWN.getIndex()]);
                this.generateDefaultFloor(llllllllllllIllIIIlIIlIlIIlIIlll, llllllllllllIllIIIlIIlIlIIlIIIII, 0, 0, llllllllllllIllIIIlIIlIlIIlIIIll.hasOpening[EnumFacing.DOWN.getIndex()]);
            }
            if (llllllllllllIllIIIlIIlIlIIlIIIll.connections[EnumFacing.UP.getIndex()] == null) {
                this.generateBoxOnFillOnly(llllllllllllIllIIIlIIlIlIIlIIlll, llllllllllllIllIIIlIIlIlIIlIIIII, 1, 4, 1, 7, 4, 6, DoubleXRoom.ROUGH_PRISMARINE);
            }
            if (llllllllllllIllIIIlIIlIlIIlIIlII.connections[EnumFacing.UP.getIndex()] == null) {
                this.generateBoxOnFillOnly(llllllllllllIllIIIlIIlIlIIlIIlll, llllllllllllIllIIIlIIlIlIIlIIIII, 8, 4, 1, 14, 4, 6, DoubleXRoom.ROUGH_PRISMARINE);
            }
            this.fillWithBlocks(llllllllllllIllIIIlIIlIlIIlIIlll, llllllllllllIllIIIlIIlIlIIlIIIII, 0, 3, 0, 0, 3, 7, DoubleXRoom.BRICKS_PRISMARINE, DoubleXRoom.BRICKS_PRISMARINE, false);
            this.fillWithBlocks(llllllllllllIllIIIlIIlIlIIlIIlll, llllllllllllIllIIIlIIlIlIIlIIIII, 15, 3, 0, 15, 3, 7, DoubleXRoom.BRICKS_PRISMARINE, DoubleXRoom.BRICKS_PRISMARINE, false);
            this.fillWithBlocks(llllllllllllIllIIIlIIlIlIIlIIlll, llllllllllllIllIIIlIIlIlIIlIIIII, 1, 3, 0, 15, 3, 0, DoubleXRoom.BRICKS_PRISMARINE, DoubleXRoom.BRICKS_PRISMARINE, false);
            this.fillWithBlocks(llllllllllllIllIIIlIIlIlIIlIIlll, llllllllllllIllIIIlIIlIlIIlIIIII, 1, 3, 7, 14, 3, 7, DoubleXRoom.BRICKS_PRISMARINE, DoubleXRoom.BRICKS_PRISMARINE, false);
            this.fillWithBlocks(llllllllllllIllIIIlIIlIlIIlIIlll, llllllllllllIllIIIlIIlIlIIlIIIII, 0, 2, 0, 0, 2, 7, DoubleXRoom.ROUGH_PRISMARINE, DoubleXRoom.ROUGH_PRISMARINE, false);
            this.fillWithBlocks(llllllllllllIllIIIlIIlIlIIlIIlll, llllllllllllIllIIIlIIlIlIIlIIIII, 15, 2, 0, 15, 2, 7, DoubleXRoom.ROUGH_PRISMARINE, DoubleXRoom.ROUGH_PRISMARINE, false);
            this.fillWithBlocks(llllllllllllIllIIIlIIlIlIIlIIlll, llllllllllllIllIIIlIIlIlIIlIIIII, 1, 2, 0, 15, 2, 0, DoubleXRoom.ROUGH_PRISMARINE, DoubleXRoom.ROUGH_PRISMARINE, false);
            this.fillWithBlocks(llllllllllllIllIIIlIIlIlIIlIIlll, llllllllllllIllIIIlIIlIlIIlIIIII, 1, 2, 7, 14, 2, 7, DoubleXRoom.ROUGH_PRISMARINE, DoubleXRoom.ROUGH_PRISMARINE, false);
            this.fillWithBlocks(llllllllllllIllIIIlIIlIlIIlIIlll, llllllllllllIllIIIlIIlIlIIlIIIII, 0, 1, 0, 0, 1, 7, DoubleXRoom.BRICKS_PRISMARINE, DoubleXRoom.BRICKS_PRISMARINE, false);
            this.fillWithBlocks(llllllllllllIllIIIlIIlIlIIlIIlll, llllllllllllIllIIIlIIlIlIIlIIIII, 15, 1, 0, 15, 1, 7, DoubleXRoom.BRICKS_PRISMARINE, DoubleXRoom.BRICKS_PRISMARINE, false);
            this.fillWithBlocks(llllllllllllIllIIIlIIlIlIIlIIlll, llllllllllllIllIIIlIIlIlIIlIIIII, 1, 1, 0, 15, 1, 0, DoubleXRoom.BRICKS_PRISMARINE, DoubleXRoom.BRICKS_PRISMARINE, false);
            this.fillWithBlocks(llllllllllllIllIIIlIIlIlIIlIIlll, llllllllllllIllIIIlIIlIlIIlIIIII, 1, 1, 7, 14, 1, 7, DoubleXRoom.BRICKS_PRISMARINE, DoubleXRoom.BRICKS_PRISMARINE, false);
            this.fillWithBlocks(llllllllllllIllIIIlIIlIlIIlIIlll, llllllllllllIllIIIlIIlIlIIlIIIII, 5, 1, 0, 10, 1, 4, DoubleXRoom.BRICKS_PRISMARINE, DoubleXRoom.BRICKS_PRISMARINE, false);
            this.fillWithBlocks(llllllllllllIllIIIlIIlIlIIlIIlll, llllllllllllIllIIIlIIlIlIIlIIIII, 6, 2, 0, 9, 2, 3, DoubleXRoom.ROUGH_PRISMARINE, DoubleXRoom.ROUGH_PRISMARINE, false);
            this.fillWithBlocks(llllllllllllIllIIIlIIlIlIIlIIlll, llllllllllllIllIIIlIIlIlIIlIIIII, 5, 3, 0, 10, 3, 4, DoubleXRoom.BRICKS_PRISMARINE, DoubleXRoom.BRICKS_PRISMARINE, false);
            this.setBlockState(llllllllllllIllIIIlIIlIlIIlIIlll, DoubleXRoom.SEA_LANTERN, 6, 2, 3, llllllllllllIllIIIlIIlIlIIlIIIII);
            this.setBlockState(llllllllllllIllIIIlIIlIlIIlIIlll, DoubleXRoom.SEA_LANTERN, 9, 2, 3, llllllllllllIllIIIlIIlIlIIlIIIII);
            if (llllllllllllIllIIIlIIlIlIIlIIIll.hasOpening[EnumFacing.SOUTH.getIndex()]) {
                this.generateWaterBox(llllllllllllIllIIIlIIlIlIIlIIlll, llllllllllllIllIIIlIIlIlIIlIIIII, 3, 1, 0, 4, 2, 0, false);
            }
            if (llllllllllllIllIIIlIIlIlIIlIIIll.hasOpening[EnumFacing.NORTH.getIndex()]) {
                this.generateWaterBox(llllllllllllIllIIIlIIlIlIIlIIlll, llllllllllllIllIIIlIIlIlIIlIIIII, 3, 1, 7, 4, 2, 7, false);
            }
            if (llllllllllllIllIIIlIIlIlIIlIIIll.hasOpening[EnumFacing.WEST.getIndex()]) {
                this.generateWaterBox(llllllllllllIllIIIlIIlIlIIlIIlll, llllllllllllIllIIIlIIlIlIIlIIIII, 0, 1, 3, 0, 2, 4, false);
            }
            if (llllllllllllIllIIIlIIlIlIIlIIlII.hasOpening[EnumFacing.SOUTH.getIndex()]) {
                this.generateWaterBox(llllllllllllIllIIIlIIlIlIIlIIlll, llllllllllllIllIIIlIIlIlIIlIIIII, 11, 1, 0, 12, 2, 0, false);
            }
            if (llllllllllllIllIIIlIIlIlIIlIIlII.hasOpening[EnumFacing.NORTH.getIndex()]) {
                this.generateWaterBox(llllllllllllIllIIIlIIlIlIIlIIlll, llllllllllllIllIIIlIIlIlIIlIIIII, 11, 1, 7, 12, 2, 7, false);
            }
            if (llllllllllllIllIIIlIIlIlIIlIIlII.hasOpening[EnumFacing.EAST.getIndex()]) {
                this.generateWaterBox(llllllllllllIllIIIlIIlIlIIlIIlll, llllllllllllIllIIIlIIlIlIIlIIIII, 15, 1, 3, 15, 2, 4, false);
            }
            return true;
        }
        
        public DoubleXRoom(final EnumFacing llllllllllllIllIIIlIIlIlIIllIIll, final RoomDefinition llllllllllllIllIIIlIIlIlIIlIlllI, final Random llllllllllllIllIIIlIIlIlIIllIIIl) {
            super(1, llllllllllllIllIIIlIIlIlIIllIIll, llllllllllllIllIIIlIIlIlIIlIlllI, 2, 1, 1);
        }
    }
    
    static class YZDoubleRoomFitHelper implements MonumentRoomFitHelper
    {
        @Override
        public Piece create(final EnumFacing lIlIIlIllIlIlI, final RoomDefinition lIlIIlIllIlIIl, final Random lIlIIlIllIlIII) {
            lIlIIlIllIlIIl.claimed = true;
            lIlIIlIllIlIIl.connections[EnumFacing.NORTH.getIndex()].claimed = true;
            lIlIIlIllIlIIl.connections[EnumFacing.UP.getIndex()].claimed = true;
            lIlIIlIllIlIIl.connections[EnumFacing.NORTH.getIndex()].connections[EnumFacing.UP.getIndex()].claimed = true;
            return new DoubleYZRoom(lIlIIlIllIlIlI, lIlIIlIllIlIIl, lIlIIlIllIlIII);
        }
        
        @Override
        public boolean fits(final RoomDefinition lIlIIlIlllIIlI) {
            if (lIlIIlIlllIIlI.hasOpening[EnumFacing.NORTH.getIndex()] && !lIlIIlIlllIIlI.connections[EnumFacing.NORTH.getIndex()].claimed && lIlIIlIlllIIlI.hasOpening[EnumFacing.UP.getIndex()] && !lIlIIlIlllIIlI.connections[EnumFacing.UP.getIndex()].claimed) {
                final RoomDefinition lIlIIlIlllIIIl = lIlIIlIlllIIlI.connections[EnumFacing.NORTH.getIndex()];
                return lIlIIlIlllIIIl.hasOpening[EnumFacing.UP.getIndex()] && !lIlIIlIlllIIIl.connections[EnumFacing.UP.getIndex()].claimed;
            }
            return false;
        }
        
        private YZDoubleRoomFitHelper() {
        }
    }
    
    public static class MonumentBuilding extends Piece
    {
        private /* synthetic */ RoomDefinition coreRoom;
        private /* synthetic */ RoomDefinition sourceRoom;
        private final /* synthetic */ List<Piece> childPieces;
        
        private void generateEntranceWall(final World llllllllllIlllIlIlllllIIlIIIIIII, final Random llllllllllIlllIlIlllllIIIlllllll, final StructureBoundingBox llllllllllIlllIlIlllllIIIllllIII) {
            if (this.doesChunkIntersect(llllllllllIlllIlIlllllIIIllllIII, 15, 20, 42, 21)) {
                this.fillWithBlocks(llllllllllIlllIlIlllllIIlIIIIIII, llllllllllIlllIlIlllllIIIllllIII, 15, 0, 21, 42, 0, 21, MonumentBuilding.ROUGH_PRISMARINE, MonumentBuilding.ROUGH_PRISMARINE, false);
                this.generateWaterBox(llllllllllIlllIlIlllllIIlIIIIIII, llllllllllIlllIlIlllllIIIllllIII, 26, 1, 21, 31, 3, 21, false);
                this.fillWithBlocks(llllllllllIlllIlIlllllIIlIIIIIII, llllllllllIlllIlIlllllIIIllllIII, 21, 12, 21, 36, 12, 21, MonumentBuilding.ROUGH_PRISMARINE, MonumentBuilding.ROUGH_PRISMARINE, false);
